Workbook

Sheet CONFIG
A1: PARAMETRO | B1: VALOR | C1: NOTA
A2: TC_EUR_USD | B2: 1.17 | C2: Tipo de cambio EUR a USD
A3: TC_USD_RD | B3: 63 | C3: Tipo de cambio USD a RD$
A4: MONEDA | B4: USD | C4: Moneda visible al cliente
A5: INCOTERM | B5: EXW | C5: Incoterm por defecto
A6: MARGEN_ARIAS_BASE | B6: 0.2 | C6: Referencia orientativa. El margen real se define por proyecto en INPUT.
A7: MERMA_OBRA | B7: 0.05 | C7: Merma estandar en obra (5%)
A8: DIAS_VALIDEZ | B8: 15 | C8: Dias de validez comercial
A9: LOGISTICA_FOB | C9: Pendiente tarifa Amura Cargo
A10: LOGISTICA_CIF | C10: Pendiente tarifa Amura Cargo
A11: FECHA_ACTUALIZACION_TC | B11: 2026-04-09 | C11: Fecha de actualizacion

Sheet PRODUCT
A1: ARIAS GROUP CARIBE — MAESTRO DE PRODUCTOS GYPSOTECH · Tarifa Abril 2026 · EXW Tarancón
A2: FAMILIA | B2: SUBFAMILIA | C2: NOMBRE | D2: CÓDIGO | E2: NORMA | F2: ANCHO MM | G2: ESPESOR MM | H2: LONGITUD MM | I2: M2 PLACA | J2: PESO KG M2 | K2: PESO PLACA KG | L2: UD PALE | M2: M2 PALE | N2: PESO PALE KG | O2: UD VENTA | P2: UD LOGISTICA | Q2: PVP ORIGEN EUR | R2: UNIDAD PRECIO | S2: DESCUENTO DISTRIBUIDOR | T2: PRECIO ARIAS EUR | U2: HS CODE | V2: RENDIMIENTO_M2 (solo cotización por sistemas) | W2: USO | X2: ACTIVO | Y2: DISPO TARANCON | Z2: NOTAS
A3: PLACAS | B3: STD | C3: STD BA 6mm 1200×2500 | D3: P00A006250AI | E3: EN 520 | F3: 1200 | G3: 6 | H3: 2500 | I3: =F3*H3/1000000 | J3: 5.3 | K3: =I3*J3 | O3: Placa | P3: Palé | Q3: 5.99 | R3: €/m² | S3: 0.5 | T3: =Q3*S3 | U3: 6809.11.00 | W3: Tabiques, trasdosados y techos continuos interiores | X3: SI | Y3: Solo Calliano | Z3: Solo disponible desde Calliano — no en Tarancón
A4: PLACAS | B4: STD | C4: STD BA 6mm 1200×3000 | D4: P00A006300A1 | E4: EN 520 | F4: 1200 | G4: 6 | H4: 3000 | I4: =F4*H4/1000000 | J4: 5.3 | K4: =I4*J4 | O4: Placa | P4: Palé | Q4: 5.99 | R4: €/m² | S4: 0.5 | T4: =Q4*S4 | U4: 6809.11.00 | W4: Tabiques, trasdosados y techos continuos interiores | X4: SI | Y4: Solo Calliano | Z4: Solo disponible desde Calliano — no en Tarancón
A5: PLACAS | B5: STD | C5: STD BA 10mm 1200×2000 | D5: P00A000200A0 | E5: EN 520 | F5: 1200 | G5: 9.5 | H5: 2000 | I5: =F5*H5/1000000 | J5: 7.7 | K5: =I5*J5 | L5: 60 | M5: =I5*L5 | N5: =K5*L5+32 | O5: Placa | P5: Palé | Q5: 4.96 | R5: €/m² | S5: 0.5 | T5: =Q5*S5 | U5: 6809.11.00 | W5: Tabiques, trasdosados y techos continuos interiores | X5: SI | Y5: SI
A6: PLACAS | B6: STD | C6: STD BA 10mm 1200×2500 | D6: P00A000250A0 | E6: EN 520 | F6: 1200 | G6: 9.5 | H6: 2500 | I6: =F6*H6/1000000 | J6: 7.7 | K6: =I6*J6 | L6: 48 | M6: =I6*L6 | N6: =K6*L6+32 | O6: Placa | P6: Palé | Q6: 4.96 | R6: €/m² | S6: 0.5 | T6: =Q6*S6 | U6: 6809.11.00 | W6: Tabiques, trasdosados y techos continuos interiores | X6: SI | Y6: SI
A7: PLACAS | B7: STD | C7: STD BA 10mm 1200×2600 | D7: P00A000260A0 | E7: EN 520 | F7: 1200 | G7: 9.5 | H7: 2600 | I7: =F7*H7/1000000 | J7: 7.7 | K7: =I7*J7 | L7: 48 | M7: =I7*L7 | N7: =K7*L7+32 | O7: Placa | P7: Palé | Q7: 4.96 | R7: €/m² | S7: 0.5 | T7: =Q7*S7 | U7: 6809.11.00 | W7: Tabiques, trasdosados y techos continuos interiores | X7: SI | Y7: SI
A8: PLACAS | B8: STD | C8: STD BA 10mm 1200×2700 | D8: P00A000270A0 | E8: EN 520 | F8: 1200 | G8: 9.5 | H8: 2700 | I8: =F8*H8/1000000 | J8: 7.7 | K8: =I8*J8 | L8: 48 | M8: =I8*L8 | N8: =K8*L8+32 | O8: Placa | P8: Palé | Q8: 4.96 | R8: €/m² | S8: 0.5 | T8: =Q8*S8 | U8: 6809.11.00 | W8: Tabiques, trasdosados y techos continuos interiores | X8: SI | Y8: SI
A9: PLACAS | B9: STD | C9: STD BA 10mm 1200×3000 | D9: P00A000300A0 | E9: EN 520 | F9: 1200 | G9: 9.5 | H9: 3000 | I9: =F9*H9/1000000 | J9: 7.7 | K9: =I9*J9 | L9: 48 | M9: =I9*L9 | N9: =K9*L9+32 | O9: Placa | P9: Palé | Q9: 4.96 | R9: €/m² | S9: 0.5 | T9: =Q9*S9 | U9: 6809.11.00 | W9: Tabiques, trasdosados y techos continuos interiores | X9: SI | Y9: SI
A10: PLACAS | B10: STD | C10: STD BA 13mm 1200×2000 | D10: P00A003200A0 | E10: EN 520 | F10: 1200 | G10: 12.5 | H10: 2000 | I10: =F10*H10/1000000 | J10: 8.7 | K10: =I10*J10 | L10: 60 | M10: =I10*L10 | N10: =K10*L10+32 | O10: Placa | P10: Palé | Q10: 4.03 | R10: €/m² | S10: 0.5 | T10: =Q10*S10 | U10: 6809.11.00 | W10: Tabiques, trasdosados y techos continuos interiores | X10: SI | Y10: SI
A11: PLACAS | B11: STD | C11: STD BA 13mm 1200×2400 | D11: P00A003240A0 | E11: EN 520 | F11: 1200 | G11: 12.5 | H11: 2400 | I11: =F11*H11/1000000 | J11: 8.7 | K11: =I11*J11 | L11: 48 | M11: =I11*L11 | N11: =K11*L11+32 | O11: Placa | P11: Palé | Q11: 4.03 | R11: €/m² | S11: 0.5 | T11: =Q11*S11 | U11: 6809.11.00 | W11: Tabiques, trasdosados y techos continuos interiores | X11: SI | Y11: SI
A12: PLACAS | B12: STD | C12: STD BA 13mm 1200×2500 | D12: P00A003250A0 | E12: EN 520 | F12: 1200 | G12: 12.5 | H12: 2500 | I12: =F12*H12/1000000 | J12: 8.7 | K12: =I12*J12 | L12: 48 | M12: =I12*L12 | N12: =K12*L12+32 | O12: Placa | P12: Palé | Q12: 4.03 | R12: €/m² | S12: 0.5 | T12: =Q12*S12 | U12: 6809.11.00 | W12: Tabiques, trasdosados y techos continuos interiores | X12: SI | Y12: SI
A13: PLACAS | B13: STD | C13: STD BA 13mm 1200×2600 | D13: P00A003260A0 | E13: EN 520 | F13: 1200 | G13: 12.5 | H13: 2600 | I13: =F13*H13/1000000 | J13: 8.7 | K13: =I13*J13 | L13: 48 | M13: =I13*L13 | N13: =K13*L13+32 | O13: Placa | P13: Palé | Q13: 4.03 | R13: €/m² | S13: 0.5 | T13: =Q13*S13 | U13: 6809.11.00 | W13: Tabiques, trasdosados y techos continuos interiores | X13: SI | Y13: SI
A14: PLACAS | B14: STD | C14: STD BA 13mm 1200×2700 | D14: P00A003270A0 | E14: EN 520 | F14: 1200 | G14: 12.5 | H14: 2700 | I14: =F14*H14/1000000 | J14: 8.7 | K14: =I14*J14 | L14: 48 | M14: =I14*L14 | N14: =K14*L14+32 | O14: Placa | P14: Palé | Q14: 4.03 | R14: €/m² | S14: 0.5 | T14: =Q14*S14 | U14: 6809.11.00 | W14: Tabiques, trasdosados y techos continuos interiores | X14: SI | Y14: SI
A15: PLACAS | B15: STD | C15: STD BA 13mm 1200×2800 | D15: P00A003280A0 | E15: EN 520 | F15: 1200 | G15: 12.5 | H15: 2800 | I15: =F15*H15/1000000 | J15: 8.7 | K15: =I15*J15 | L15: 48 | M15: =I15*L15 | N15: =K15*L15+32 | O15: Placa | P15: Palé | Q15: 4.03 | R15: €/m² | S15: 0.5 | T15: =Q15*S15 | U15: 6809.11.00 | W15: Tabiques, trasdosados y techos continuos interiores | X15: SI | Y15: SI
A16: PLACAS | B16: STD | C16: STD BA 13mm 1200×3000 | D16: P00A003300A0 | E16: EN 520 | F16: 1200 | G16: 12.5 | H16: 3000 | I16: =F16*H16/1000000 | J16: 8.7 | K16: =I16*J16 | L16: 36 | M16: =I16*L16 | N16: =K16*L16+32 | O16: Placa | P16: Palé | Q16: 4.03 | R16: €/m² | S16: 0.5 | T16: =Q16*S16 | U16: 6809.11.00 | W16: Tabiques, trasdosados y techos continuos interiores | X16: SI | Y16: SI
... A25: PLACAS | B25: STD | C25: STD BA 18mm 1200×3000 | D25: P00A008300A0 | E25: EN 520 | F25: 1200 | G25: 18 | H25: 3000 | I25: =F25*H25/1000000 | J25: 14.2 | K25: =I25*J25 | L25: 24 | M25: =I25*L25 | N25: =K25*L25+32 | O25: Placa | P25: Palé | Q25: 5.99 | R25: €/m² | S25: 0.5 | T25: =Q25*S25 | U25: 6809.11.00 | W25: Tabiques, trasdosados y techos continuos interiores | X25: SI | Y25: SI
A26: PLACAS | B26: STD Zero | C26: STD Zero BA 13mm 1200×2000 | D26: P00AZ03200A0 | E26: EN 520 | F26: 1200 | G26: 12.5 | H26: 2000 | I26: =F26*H26/1000000 | J26: 8.7 | K26: =I26*J26 | O26: Placa | P26: Palé | Q26: 17.6 | R26: €/m² | S26: 0.5 | T26: =Q26*S26 | U26: 6809.11.00 | W26: Tabiques trasdosados techos — Euroclase A1 reacción al fuego | X26: SI | Y26: Solo Calliano | Z26: Solo disponible desde Calliano — no en Tarancón
A27: PLACAS | B27: STD Zero | C27: STD Zero BA 13mm 1200×3000 | D27: P00AZ03300A2 | E27: EN 520 | F27: 1200 | G27: 12.5 | H27: 3000 | I27: =F27*H27/1000000 | J27: 8.7 | K27: =I27*J27 | O27: Placa | P27: Palé | Q27: 17.6 | R27: €/m² | S27: 0.5 | T27: =Q27*S27 | U27: 6809.11.00 | W27: Tabiques trasdosados techos — Euroclase A1 reacción al fuego | X27: SI | Y27: Solo Calliano | Z27: Solo disponible desde Calliano — no en Tarancón
A28: PLACAS | B28: STD Zero | C28: STD Zero BA 15mm 1200×3000 | D28: P00AZ05300A2 | E28: EN 520 | F28: 1200 | G28: 15 | H28: 3000 | I28: =F28*H28/1000000 | J28: 11.6 | K28: =I28*J28 | O28: Placa | P28: Palé | Q28: 20.5 | R28: €/m² | S28: 0.5 | T28: =Q28*S28 | U28: 6809.11.00 | W28: Tabiques trasdosados techos — Euroclase A1 reacción al fuego | X28: SI | Y28: Solo Calliano | Z28: Solo disponible desde Calliano — no en Tarancón
A29: PLACAS | B29: SIMPLY | C29: GypsoSIMPLY BA 13mm 1200×2000 | D29: P00Y003200A0 | E29: EN 520 | F29: 1200 | G29: 12.5 | H29: 2000 | I29: =F29*H29/1000000 | J29: 7.8 | K29: =I29*J29 | L29: 72 | M29: =I29*L29 | N29: =K29*L29+32 | O29: Placa | P29: Palé | Q29: 4.63 | R29: €/m² | S29: 0.5 | T29: =Q29*S29 | U29: 6809.11.00 | W29: Placa aligerada — mismas prestaciones que STD con menor peso | X29: SI | Y29: SI
A30: PLACAS | B30: SIMPLY | C30: GypsoSIMPLY BA 13mm 1200×2500 | D30: P00Y003250A0 | E30: EN 520 | F30: 1200 | G30: 12.5 | H30: 2500 | I30: =F30*H30/1000000 | J30: 7.8 | K30: =I30*J30 | L30: 48 | M30: =I30*L30 | N30: =K30*L30+32 | O30: Placa | P30: Palé | Q30: 4.63 | R30: €/m² | S30: 0.5 | T30: =Q30*S30 | U30: 6809.11.00 | W30: Placa aligerada — mismas prestaciones que STD con menor peso | X30: SI | Y30: SI
A31: PLACAS | B31: SIMPLY | C31: GypsoSIMPLY BA 13mm 1200×2800 | D31: P00Y003280A0 | E31: EN 520 | F31: 1200 | G31: 12.5 | H31: 2800 | I31: =F31*H31/1000000 | J31: 7.8 | K31: =I31*J31 | L31: 48 | M31: =I31*L31 | N31: =K31*L31+32 | O31: Placa | P31: Palé | Q31: 4.63 | R31: €/m² | S31: 0.5 | T31: =Q31*S31 | U31: 6809.11.00 | W31: Placa aligerada — mismas prestaciones que STD con menor peso | X31: SI | Y31: SI
A32: PLACAS | B32: SIMPLY | C32: GypsoSIMPLY BA 13mm 1200×3000 | D32: P00Y003300A0 | E32: EN 520 | F32: 1200 | G32: 12.5 | H32: 3000 | I32: =F32*H32/1000000 | J32: 7.8 | K32: =I32*J32 | L32: 48 | M32: =I32*L32 | N32: =K32*L32+32 | O32: Placa | P32: Palé | Q32: 4.63 | R32: €/m² | S32: 0.5 | T32: =Q32*S32 | U32: 6809.11.00 | W32: Placa aligerada — mismas prestaciones que STD con menor peso | X32: SI | Y32: SI
A33: PLACAS | B33: AQUA H2 | C33: AQUA H2 BA 13mm 1200×2000 | D33: P00H003200A0 | E33: EN 520 | F33: 1200 | G33: 12.5 | H33: 2000 | I33: =F33*H33/1000000 | J33: 8.7 | K33: =I33*J33 | L33: 60 | M33: =I33*L33 | N33: =K33*L33+32 | O33: Placa | P33: Palé | Q33: 6.71 | R33: €/m² | S33: 0.5 | T33: =Q33*S33 | U33: 6809.11.00 | W33: Humedad <10% — zonas húmedas interiores | X33: SI | Y33: SI
A34: PLACAS | B34: AQUA H2 | C34: AQUA H2 BA 13mm 1200×2500 | D34: P00H003250A0 | E34: EN 520 | F34: 1200 | G34: 12.5 | H34: 2500 | I34: =F34*H34/1000000 | J34: 8.7 | K34: =I34*J34 | L34: 48 | M34: =I34*L34 | N34: =K34*L34+32 | O34: Placa | P34: Palé | Q34: 6.71 | R34: €/m² | S34: 0.5 | T34: =Q34*S34 | U34: 6809.11.00 | W34: Humedad <10% — zonas húmedas interiores | X34: SI | Y34: SI
A35: PLACAS | B35: AQUA H2 | C35: AQUA H2 BA 13mm 1200×2600 | D35: P00H003260A0 | E35: EN 520 | F35: 1200 | G35: 12.5 | H35: 2600 | I35: =F35*H35/1000000 | J35: 8.7 | K35: =I35*J35 | L35: 48 | M35: =I35*L35 | N35: =K35*L35+32 | O35: Placa | P35: Palé | Q35: 6.71 | R35: €/m² | S35: 0.5 | T35: =Q35*S35 | U35: 6809.11.00 | W35: Humedad <10% — zonas húmedas interiores | X35: SI | Y35: SI
A36: PLACAS | B36: AQUA H2 | C36: AQUA H2 BA 13mm 1200×2800 | D36: P00H003280A0 | E36: EN 520 | F36: 1200 | G36: 12.5 | H36: 2800 | I36: =F36*H36/1000000 | J36: 8.7 | K36: =I36*J36 | L36: 36 | M36: =I36*L36 | N36: =K36*L36+32 | O36: Placa | P36: Palé | Q36: 6.71 | R36: €/m² | S36: 0.5 | T36: =Q36*S36 | U36: 6809.11.00 | W36: Humedad <10% — zonas húmedas interiores | X36: SI | Y36: SI
A37: PLACAS | B37: AQUA H2 | C37: AQUA H2 BA 13mm 1200×3000 | D37: P00H003300A0 | E37: EN 520 | F37: 1200 | G37: 12.5 | H37: 3000 | I37: =F37*H37/1000000 | J37: 8.7 | K37: =I37*J37 | L37: 36 | M37: =I37*L37 | N37: =K37*L37+32 | O37: Placa | P37: Palé | Q37: 6.71 | R37: €/m² | S37: 0.5 | T37: =Q37*S37 | U37: 6809.11.00 | W37: Humedad <10% — zonas húmedas interiores | X37: SI | Y37: SI
A38: PLACAS | B38: AQUA H2 | C38: AQUA H2 BA 15mm 1200×2000 | D38: P00H005200A0 | E38: EN 520 | F38: 1200 | G38: 15 | H38: 2000 | I38: =F38*H38/1000000 | J38: 8.7 | K38: =I38*J38 | L38: 36 | M38: =I38*L38 | N38: =K38*L38+32 | O38: Placa | P38: Palé | Q38: 7.73 | R38: €/m² | S38: 0.5 | T38: =Q38*S38 | U38: 6809.11.00 | W38: Humedad <10% — zonas húmedas interiores | X38: SI | Y38: SI
A39: PLACAS | B39: AQUA H2 | C39: AQUA H2 BA 15mm 1200×2600 | D39: P00H005260A0 | E39: EN 520 | F39: 1200 | G39: 15 | H39: 2600 | I39: =F39*H39/1000000 | J39: 8.7 | K39: =I39*J39 | L39: 24 | M39: =I39*L39 | N39: =K39*L39+32 | O39: Placa | P39: Palé | Q39: 7.73 | R39: €/m² | S39: 0.5 | T39: =Q39*S39 | U39: 6809.11.00 | W39: Humedad <10% — zonas húmedas interiores | X39: SI | Y39: SI
A40: PLACAS | B40: AQUA H2 | C40: AQUA H2 BA 15mm 1200×3000 | D40: P00H005300A0 | E40: EN 520 | F40: 1200 | G40: 15 | H40: 3000 | I40: =F40*H40/1000000 | J40: 8.7 | K40: =I40*J40 | L40: 24 | M40: =I40*L40 | N40: =K40*L40+32 | O40: Placa | P40: Palé | Q40: 7.73 | R40: €/m² | S40: 0.5 | T40: =Q40*S40 | U40: 6809.11.00 | W40: Humedad <10% — zonas húmedas interiores | X40: SI | Y40: SI
... A60: PLACAS | B60: FOCUS Ultra | C60: FOCUS ULTRA BA 25mm 1200×2000 | D60: P00F004200A0 | E60: EN 520 | F60: 1200 | G60: 25 | H60: 2000 | I60: =F60*H60/1000000 | J60: 22 | K60: =I60*J60 | L60: 24 | M60: =I60*L60 | N60: =K60*L60+32 | O60: Placa | P60: Palé | Q60: 13.57 | R60: €/m² | S60: 0.5 | T60: =Q60*S60 | U60: 6809.11.00 | W60: Protección pasiva al fuego — fibra de vidrio y vermiculita | X60: SI | Y60: SI
A61: PLACAS | B61: FOCUS Zero | C61: FOCUS ZERO BA 13mm 1200×2500 | D61: P00FZ03250A0 | E61: EN 520 | F61: 1200 | G61: 12.5 | H61: 2500 | I61: =F61*H61/1000000 | J61: 10.8 | K61: =I61*J61 | O61: Placa | P61: Palé | Q61: 22.05 | R61: €/m² | S61: 0.5 | T61: =Q61*S61 | U61: 6809.11.00 | W61: Protección pasiva al fuego — fibra de vidrio y vermiculita | X61: SI | Y61: Solo Calliano | Z61: Solo disponible desde Calliano — no en Tarancón
A62: PLACAS | B62: FOCUS Zero | C62: FOCUS ZERO BA 13mm 1200×3000 | D62: P00FZ03300A2 | E62: EN 520 | F62: 1200 | G62: 12.5 | H62: 3000 | I62: =F62*H62/1000000 | J62: 10.8 | K62: =I62*J62 | O62: Placa | P62: Palé | Q62: 22.05 | R62: €/m² | S62: 0.5 | T62: =Q62*S62 | U62: 6809.11.00 | W62: Protección pasiva al fuego — fibra de vidrio y vermiculita | X62: SI | Y62: Solo Calliano | Z62: Solo disponible desde Calliano — no en Tarancón
A63: PLACAS | B63: FOCUS Zero | C63: FOCUS ZERO BA 15mm 1200×3000 | D63: P00FZ05300A2 | E63: EN 520 | F63: 1200 | G63: 15 | H63: 3000 | I63: =F63*H63/1000000 | J63: 13.6 | K63: =I63*J63 | O63: Placa | P63: Palé | Q63: 23.88 | R63: €/m² | S63: 0.5 | T63: =Q63*S63 | U63: 6809.11.00 | W63: Protección pasiva al fuego — fibra de vidrio y vermiculita | X63: SI | Y63: Solo Calliano | Z63: Solo disponible desde Calliano — no en Tarancón
A64: PLACAS | B64: SILENS | C64: GypsoSILENS BA 13mm 1200×2500 | D64: P00GS03250A0 | E64: EN 520 | F64: 1200 | G64: 13 | H64: 2500 | I64: =F64*H64/1000000 | J64: 11.9 | K64: =I64*J64 | L64: 36 | M64: =I64*L64 | N64: =K64*L64+32 | O64: Placa | P64: Palé | Q64: 7.42 | R64: €/m² | S64: 0.5 | T64: =Q64*S64 | U64: 6809.11.00 | W64: Densidad >800 kg/m³ — alto aislamiento acústico | X64: SI | Y64: SI
A65: PLACAS | B65: SILENS | C65: GypsoSILENS BA 13mm 1200×2600 | D65: P00GS03260A0 | E65: EN 520 | F65: 1200 | G65: 13 | H65: 2600 | I65: =F65*H65/1000000 | J65: 11.9 | K65: =I65*J65 | L65: 36 | M65: =I65*L65 | N65: =K65*L65+32 | O65: Placa | P65: Palé | Q65: 7.42 | R65: €/m² | S65: 0.5 | T65: =Q65*S65 | U65: 6809.11.00 | W65: Densidad >800 kg/m³ — alto aislamiento acústico | X65: SI | Y65: SI
A66: PLACAS | B66: SILENS | C66: GypsoSILENS BA 13mm 1200×3000 | D66: P00GS03300A0 | E66: EN 520 | F66: 1200 | G66: 13 | H66: 3000 | I66: =F66*H66/1000000 | J66: 11.9 | K66: =I66*J66 | L66: 24 | M66: =I66*L66 | N66: =K66*L66+32 | O66: Placa | P66: Palé | Q66: 7.42 | R66: €/m² | S66: 0.5 | T66: =Q66*S66 | U66: 6809.11.00 | W66: Densidad >800 kg/m³ — alto aislamiento acústico | X66: SI | Y66: SI
A67: PLACAS | B67: LIGNUM | C67: GypsoLIGNUM BA 13mm 1200×2000 | D67: P00LB03200AC | E67: EN 520 | F67: 1200 | G67: 12.5 | H67: 2000 | I67: =F67*H67/1000000 | J67: 12.8 | K67: =I67*J67 | L67: 36 | M67: =I67*L67 | N67: =K67*L67+32 | O67: Placa | P67: Palé | Q67: 11.73 | R67: €/m² | S67: 0.5 | T67: =Q67*S67 | U67: 6809.11.00 | W67: Densidad >1000 kg/m³ — fuego impacto humedad prestaciones acústicas | X67: SI | Y67: SI
...

Sheet SYSTEM
A1: FAM | B1: PRODUCTO | C1: CÓDIGO | D1: CONTENIDO UNIDAD LOGÍSTICA | E1: PRECIO ARIAS €/unidad logística | F1: PRECIO ARIAS €/ud o €/ml real | G1: RENDIMIENTO / m² sistema | H1: UNIDAD RENDIMIENTO | I1: COSTE €/m² sistema
A2: SISTEMA 1 — TRASDOSADO SEMI-DIRECTO STD | Omega 82/16 · STD BA 12,5 mm - 1200x2500 · Sep. Omega 600 mm
A3: 2 | B3: Perfil Omega 82/16 - 3000 mm | C3: E168218300Z1 | D3: Barra 3000 mm | E3: 2,00 €/barra | F3: 0,665 €/ml | G3: 1.67 | H3: ml/m² | I3: 1.11
A4: 1 | B4: Gypsotech STD BA 12,5 mm - 1200x2500 | C4: P00A003250A0 | D4: Palé 48 ud / 144 m² | E4: 2,02 €/m² | F4: 2,015 €/m² | G4: 1.05 | H4: m²/m² | I4: 2.12
A5: 3 | B5: Tornillo Fosfatado PM PC Ø3,5x25 mm - 1000 ud | C5: 304101 | D5: Caja 1000 ud | E5: 7,00 €/caja | F5: 0,007 €/ud | G5: 15 | H5: ud/m² | I5: 0.1
A6: 4 | B6: Fassajoint 1H - Saco 10 kg | C6: 351E1 | D6: Saco 10 kg | E6: 6,63 €/saco | F6: 0,663 €/kg | G6: 0.35 | H6: kg/m² | I6: 0.23
A7: 5 | B7: Cinta de Juntas 50 mm - Rollo 150 ml | C7: 304058 | D7: Rollo 150 ml | E7: 4,19 €/rollo | F7: 0,028 €/ml | G7: 1.1 | H7: ml/m² | I7: 0.03
A8: 5 | B8: Banda Estanca Monoadhesiva 70 mm - Rollo 30 ml | C8: 304076 | D8: Rollo 30 ml | E8: 8,71 €/rollo | F8: 0,290 €/ml | G8: 1.72 | H8: ml/m² | I8: 0.5
A9: TOTAL COSTE MATERIAL / m² sistema | I9: 4.09 €
A12: SISTEMA 2 — TRASDOSADO SEMI-DIRECTO AQUA H2 | Omega 82/16 · AQUA H2 BA 12,5 mm - 1200x2500 · Sep. Omega 600 mm
A13: 2
A14: 1 | B14: Gypsotech AQUA H2 BA 12,5 mm - 1200x2500 | C14: P00H003250A0 | D14: Palé 48 ud / 144 m² | E14: 3,35 €/m² | F14: 3,355 €/m² | G14: 1.05 | H14: m²/m² | I14: 3.52
A15: 3 | B15: Tornillo Fosfatado PM PC Ø3,5x25 mm - 1000 ud | C15: 304101 | D15: Caja 1000 ud | E15: 7,00 €/caja | F15: 0,007 €/ud | G15: 15 | H15: ud/m² | I15: 0.1
A16: 4 | B16: Fassajoint 1H - Saco 10 kg | C16: 351E1 | D16: Saco 10 kg | E16: 6,63 €/saco | F16: 0,663 €/kg | G16: 0.35 | H16: kg/m² | I16: 0.23
A17: 5 | B17: Cinta de Juntas 50 mm - Rollo 150 ml | C17: 304058 | D17: Rollo 150 ml | E17: 4,19 €/rollo | F17: 0,028 €/ml | G17: 1.1 | H17: ml/m² | I17: 0.03
A18: 5 | B18: Banda Estanca Monoadhesiva 70 mm - Rollo 30 ml | C18: 304076 | D18: Rollo 30 ml | E18: 8,71 €/rollo | F18: 0,290 €/ml | G18: 1.72 | H18: ml/m² | I18: 0.5
A19: TOTAL COSTE MATERIAL / m² sistema | I19: 5.49 €
A22: SISTEMA 3A — TRASDOSADO STD | Mont.48 + Rail 48 · STD BA 12,5 mm - 1200x2500 · Sep. 400 mm
A23: 2 | B23: Montante 48/35 Z1 - 2990 mm | C23: C344836299A | D23: Barra 2990 mm | E23: 2,09 €/barra | F23: 0,700 €/ml | G23: 2.5 | H23: ml/m² | I23: 1.75
A24: 2
A25: 1 | B25: Gypsotech STD BA 12,5 mm - 1200x2500 | C25: P00A003250A0 | D25: Palé 48 ud / 144 m² | E25: 2,02 €/m² | F25: 2,015 €/m² | G25: 1.05 | H25: m²/m² | I25: 2.12
A26: 3 | B26: Tornillo Fosfatado PM PC Ø3,5x25 mm - 1000 ud | C26: 304101 | D26: Caja 1000 ud | E26: 7,00 €/caja | F26: 0,007 €/ud | G26: 15 | H26: ud/m² | I26: 0.1
A27: 3 | B27: Tornillo Cincado Metal-Metal PB Ø3,5x9,5 mm - 1000 ud | C27: 304134 | D27: Caja 1000 ud | E27: 7,19 €/caja | F27: 0,007 €/ud | G27: 3 | H27: ud/m² | I27: 0.02
A28: 4 | B28: Fassajoint 1H - Saco 10 kg | C28: 351E1 | D28: Saco 10 kg | E28: 6,63 €/saco | F28: 0,663 €/kg | G28: 0.35 | H28: kg/m² | I28: 0.23
A29: 5 | B29: Cinta de Juntas 50 mm - Rollo 150 ml | C29: 304058 | D29: Rollo 150 ml | E29: 4,19 €/rollo | F29: 0,028 €/ml | G29: 1.1 | H29: ml/m² | I29: 0.03
A30: 5 | B30: Banda Estanca Monoadhesiva 50 mm - Rollo 30 ml | C30: 304075 | D30: Rollo 30 ml | E30: 5,79 €/rollo | F30: 0,193 €/ml | G30: 1.72 | H30: ml/m² | I30: 0.33
A31: 2 | B31: Perfil Angular Z1 23x34 - 3000 mm | C31: L2334300A | D31: Barra 3000 mm | E31: 1,26 €/barra | F31: 0,420 €/ml | G31: 0.4 | H31: ml/m² | I31: 0.17
A32: TOTAL COSTE MATERIAL / m² sistema | I32: 5.31 €
A35: SISTEMA 3B — TRASDOSADO STD | Mont.48 + Rail 48 · STD BA 12,5 mm - 1200x2500 · Sep. 600 mm
A36: 2
A37: 2 | B37: Rail 48 Z1 - 3000 mm | C37: U304830300A | D37: Barra 3000 mm | E37: 1,77 €/barra | F37: 0,590 €/ml | G37: 0.95 | H37: ml/m² | I37: 0.56
A38: 1 | B38: Gypsotech STD BA 12,5 mm - 1200x2500 | C38: P00A003250A0 | D38: Palé 48 ud / 144 m² | E38: 2,02 €/m² | F38: 2,015 €/m² | G38: 1.05 | H38: m²/m² | I38: 2.12
A39: 3 | B39: Tornillo Fosfatado PM PC Ø3,5x25 mm - 1000 ud | C39: 304101 | D39: Caja 1000 ud | E39: 7,00 €/caja | F39: 0,007 €/ud | G39: 15 | H39: ud/m² | I39: 0.1
A40: 3 | B40: Tornillo Cincado Metal-Metal PB Ø3,5x9,5 mm - 1000 ud | C40: 304134 | D40: Caja 1000 ud | E40: 7,19 €/caja | F40: 0,007 €/ud | G40: 3 | H40: ud/m² | I40: 0.02
A41: 4 | B41: Fassajoint 1H - Saco 10 kg | C41: 351E1 | D41: Saco 10 kg | E41: 6,63 €/saco | F41: 0,663 €/kg | G41: 0.35 | H41: kg/m² | I41: 0.23
A42: 5 | B42: Cinta de Juntas 50 mm - Rollo 150 ml | C42: 304058 | D42: Rollo 150 ml | E42: 4,19 €/rollo | F42: 0,028 €/ml | G42: 1.1 | H42: ml/m² | I42: 0.03
A43: 5 | B43: Banda Estanca Monoadhesiva 50 mm - Rollo 30 ml | C43: 304075 | D43: Rollo 30 ml | E43: 5,79 €/rollo | F43: 0,193 €/ml | G43: 1.72 | H43: ml/m² | I43: 0.33
A44: 2 | B44: Perfil Angular Z1 23x34 - 3000 mm | C44: L2334300A | D44: Barra 3000 mm | E44: 1,26 €/barra | F44: 0,420 €/ml | G44: 0.4 | H44: ml/m² | I44: 0.17
A45: TOTAL COSTE MATERIAL / m² sistema | I45: 4.73 €
A48: SISTEMA 4A — TRASDOSADO AQUA H2 | Mont.48 + Rail 48 · AQUA H2 BA 12,5 mm - 1200x2500 · Sep. 400 mm
...

Sheet INPUT_SYSTEM
A1: Cliente | B1: Francisco Flores
A2: Proyecto | B2: Palmira
A3: SRL | B3: xxxxxx
A4: Responsable | B4: Ana Mar Pérez
A5: Fecha | B5: 46120.802
A6: N_COTIZACION
A7: Incoterm | B7: =CONFIG!B7
A8: Condiciones_Pago
A9: Validez (días) | B9: =CONFIG!B6
A10: Plazo Entrega (semanas)
A11: Moneda | B11: =CONFIG!B8
A12: AREA_TOTAL_REFERENCIAL_M2 | B12: 100
A13: Observaciones_Generales
A15: ITEM | B15: GRUPO_COMPOSICION | C15: INCLUIR | D15: SKU_FASSA | E15: FAMILIA | F15: NOMBRE_PRODUCTO | G15: AREA_APLICADA_M2 | H15: RENDIMIENTO_APLICADO | I15: UNIDAD_RENDIMIENTO | J15: MERMA_% | K15: FACTOR_AJUSTE | L15: CANTIDAD_MANUAL_OVERRIDE | M15: MARGEN_%_APLICADO | N15: OBSERVACION_ITEM
A16: 1 | B16: Placa | C16: SI | D16: C344836299B | E16: {=IFERROR(INDEX(PRODUCT!$A:$A,MATCH(D16,PRODUCT!$B:$B,0)),"")} | F16: {=IFERROR(INDEX(PRODUCT!$C:$C,MATCH(D16,PRODUCT!$B:$B,0)),"")} | G16: =$B$12 | H16: {=IFERROR(INDEX(PRODUCT!$L:$L,MATCH(D16,PRODUCT!$B:$B,0)),"")} | I16: {=IFERROR(INDEX(PRODUCT!$M:$M,MATCH(D16,PRODUCT!$B:$B,0)),"")} | J16: 0.05 | K16: 1 | L16: 105 | M16: =CONFIG!$B$4 | N16: Base muro seco
A17: 2 | B17: Perfilería | C17: SI | D17: C344836299B | E17: {=IFERROR(INDEX(PRODUCT!$A:$A,MATCH(D17,PRODUCT!$B:$B,0)),"")} | F17: {=IFERROR(INDEX(PRODUCT!$C:$C,MATCH(D17,PRODUCT!$B:$B,0)),"")} | G17: =$B$12 | H17: {=IFERROR(INDEX(PRODUCT!$L:$L,MATCH(D17,PRODUCT!$B:$B,0)),"")} | I17: {=IFERROR(INDEX(PRODUCT!$M:$M,MATCH(D17,PRODUCT!$B:$B,0)),"")} | J17: 0.05 | K17: 1 | L17: 105 | M17: =CONFIG!$B$4 | N17: Editable según cliente
A18: 3 | B18: Perfilería | C18: SI | D18: U307030300A | E18: {=IFERROR(INDEX(PRODUCT!$A:$A,MATCH(D18,PRODUCT!$B:$B,0)),"")} | F18: {=IFERROR(INDEX(PRODUCT!$C:$C,MATCH(D18,PRODUCT!$B:$B,0)),"")} | G18: =$B$12 | H18: {=IFERROR(INDEX(PRODUCT!$L:$L,MATCH(D18,PRODUCT!$B:$B,0)),"")} | I18: {=IFERROR(INDEX(PRODUCT!$M:$M,MATCH(D18,PRODUCT!$B:$B,0)),"")} | J18: 0.05 | K18: 1 | L18: 105 | M18: =CONFIG!$B$4 | N18: Editable según cliente
A19: 4 | B19: Accesorio | C19: SI | D19: 304058 | E19: {=IFERROR(INDEX(PRODUCT!$A:$A,MATCH(D19,PRODUCT!$B:$B,0)),"")} | F19: {=IFERROR(INDEX(PRODUCT!$C:$C,MATCH(D19,PRODUCT!$B:$B,0)),"")} | G19: =$B$12 | H19: {=IFERROR(INDEX(PRODUCT!$L:$L,MATCH(D19,PRODUCT!$B:$B,0)),"")} | I19: {=IFERROR(INDEX(PRODUCT!$M:$M,MATCH(D19,PRODUCT!$B:$B,0)),"")} | J19: 0.05 | K19: 1 | L19: 105 | M19: =CONFIG!$B$4 | N19: Juntas
A20: 5 | B20: Masillas | C20: SI | D20: 351E1 | E20: {=IFERROR(INDEX(PRODUCT!$A:$A,MATCH(D20,PRODUCT!$B:$B,0)),"")} | F20: {=IFERROR(INDEX(PRODUCT!$C:$C,MATCH(D20,PRODUCT!$B:$B,0)),"")} | G20: =$B$12 | H20: {=IFERROR(INDEX(PRODUCT!$L:$L,MATCH(D20,PRODUCT!$B:$B,0)),"")} | I20: {=IFERROR(INDEX(PRODUCT!$M:$M,MATCH(D20,PRODUCT!$B:$B,0)),"")} | J20: 0.05 | K20: 1 | L20: 105 | M20: =CONFIG!$B$4 | N20: Tratamiento juntas
A21: 6 | B21: Accesorio | C21: SI | D21: 304076 | E21: {=IFERROR(INDEX(PRODUCT!$A:$A,MATCH(D21,PRODUCT!$B:$B,0)),"")} | F21: {=IFERROR(INDEX(PRODUCT!$C:$C,MATCH(D21,PRODUCT!$B:$B,0)),"")} | G21: =$B$12 | H21: {=IFERROR(INDEX(PRODUCT!$L:$L,MATCH(D21,PRODUCT!$B:$B,0)),"")} | I21: {=IFERROR(INDEX(PRODUCT!$M:$M,MATCH(D21,PRODUCT!$B:$B,0)),"")} | J21: 0.05 | K21: 1 | L21: 105 | M21: =CONFIG!$B$4 | N21: Perímetro
A22: 7 | B22: Accesorio | C22: SI | D22: 1091001Y | E22: {=IFERROR(INDEX(PRODUCT!$A:$A,MATCH(D22,PRODUCT!$B:$B,0)),"")} | F22: {=IFERROR(INDEX(PRODUCT!$C:$C,MATCH(D22,PRODUCT!$B:$B,0)),"")} | G22: =$B$12 | H22: {=IFERROR(INDEX(PRODUCT!$L:$L,MATCH(D22,PRODUCT!$B:$B,0)),"")} | I22: {=IFERROR(INDEX(PRODUCT!$M:$M,MATCH(D22,PRODUCT!$B:$B,0)),"")} | J22: 0.05 | K22: 1 | L22: 105 | M22: =CONFIG!$B$4 | N22: Esquinas
E23: {=IF($D23="","",xlookup($D23,PRODUCT!$B:$B,PRODUCT!$A:$A,""))} | F23: {=IF($D23="","",xlookup($D23,PRODUCT!$B:$B,PRODUCT!$C:$C,""))} | H23: {=IF($D23="","",xlookup($D23,PRODUCT!$B:$B,PRODUCT!$L:$L,""))} | I23: {=IF($D23="","",xlookup($D23,PRODUCT!$B:$B,PRODUCT!$M:$M,""))}
E24: {=IF($D24="","",xlookup($D24,PRODUCT!$B:$B,PRODUCT!$A:$A,""))} | F24: {=IF($D24="","",xlookup($D24,PRODUCT!$B:$B,PRODUCT!$C:$C,""))} | H24: {=IF($D24="","",xlookup($D24,PRODUCT!$B:$B,PRODUCT!$L:$L,""))} | I24: {=IF($D24="","",xlookup($D24,PRODUCT!$B:$B,PRODUCT!$M:$M,""))}
E25: {=IF($D25="","",xlookup($D25,PRODUCT!$B:$B,PRODUCT!$A:$A,""))} | F25: {=IF($D25="","",xlookup($D25,PRODUCT!$B:$B,PRODUCT!$C:$C,""))} | H25: {=IF($D25="","",xlookup($D25,PRODUCT!$B:$B,PRODUCT!$L:$L,""))} | I25: {=IF($D25="","",xlookup($D25,PRODUCT!$B:$B,PRODUCT!$M:$M,""))}
E26: {=IF($D26="","",xlookup($D26,PRODUCT!$B:$B,PRODUCT!$A:$A,""))} | F26: {=IF($D26="","",xlookup($D26,PRODUCT!$B:$B,PRODUCT!$C:$C,""))} | H26: {=IF($D26="","",xlookup($D26,PRODUCT!$B:$B,PRODUCT!$L:$L,""))} | I26: {=IF($D26="","",xlookup($D26,PRODUCT!$B:$B,PRODUCT!$M:$M,""))}
E27: {=IF($D27="","",xlookup($D27,PRODUCT!$B:$B,PRODUCT!$A:$A,""))} | F27: {=IF($D27="","",xlookup($D27,PRODUCT!$B:$B,PRODUCT!$C:$C,""))} | H27: {=IF($D27="","",xlookup($D27,PRODUCT!$B:$B,PRODUCT!$L:$L,""))} | I27: {=IF($D27="","",xlookup($D27,PRODUCT!$B:$B,PRODUCT!$M:$M,""))}
E28: {=IF($D28="","",xlookup($D28,PRODUCT!$B:$B,PRODUCT!$A:$A,""))} | F28: {=IF($D28="","",xlookup($D28,PRODUCT!$B:$B,PRODUCT!$C:$C,""))} | H28: {=IF($D28="","",xlookup($D28,PRODUCT!$B:$B,PRODUCT!$L:$L,""))} | I28: {=IF($D28="","",xlookup($D28,PRODUCT!$B:$B,PRODUCT!$M:$M,""))}
E29: {=IF($D29="","",xlookup($D29,PRODUCT!$B:$B,PRODUCT!$A:$A,""))} | F29: {=IF($D29="","",xlookup($D29,PRODUCT!$B:$B,PRODUCT!$C:$C,""))} | H29: {=IF($D29="","",xlookup($D29,PRODUCT!$B:$B,PRODUCT!$L:$L,""))} | I29: {=IF($D29="","",xlookup($D29,PRODUCT!$B:$B,PRODUCT!$M:$M,""))}
E30: {=IF($D30="","",xlookup($D30,PRODUCT!$B:$B,PRODUCT!$A:$A,""))} | F30: {=IF($D30="","",xlookup($D30,PRODUCT!$B:$B,PRODUCT!$C:$C,""))} | H30: {=IF($D30="","",xlookup($D30,PRODUCT!$B:$B,PRODUCT!$L:$L,""))} | I30: {=IF($D30="","",xlookup($D30,PRODUCT!$B:$B,PRODUCT!$M:$M,""))}
E31: {=IF($D31="","",xlookup($D31,PRODUCT!$B:$B,PRODUCT!$A:$A,""))} | F31: {=IF($D31="","",xlookup($D31,PRODUCT!$B:$B,PRODUCT!$C:$C,""))} | H31: {=IF($D31="","",xlookup($D31,PRODUCT!$B:$B,PRODUCT!$L:$L,""))} | I31: {=IF($D31="","",xlookup($D31,PRODUCT!$B:$B,PRODUCT!$M:$M,""))}
E32: {=IF($D32="","",xlookup($D32,PRODUCT!$B:$B,PRODUCT!$A:$A,""))} | F32: {=IF($D32="","",xlookup($D32,PRODUCT!$B:$B,PRODUCT!$C:$C,""))} | H32: {=IF($D32="","",xlookup($D32,PRODUCT!$B:$B,PRODUCT!$L:$L,""))} | I32: {=IF($D32="","",xlookup($D32,PRODUCT!$B:$B,PRODUCT!$M:$M,""))}
E33: {=IF($D33="","",xlookup($D33,PRODUCT!$B:$B,PRODUCT!$A:$A,""))} | F33: {=IF($D33="","",xlookup($D33,PRODUCT!$B:$B,PRODUCT!$C:$C,""))} | H33: {=IF($D33="","",xlookup($D33,PRODUCT!$B:$B,PRODUCT!$L:$L,""))} | I33: {=IF($D33="","",xlookup($D33,PRODUCT!$B:$B,PRODUCT!$M:$M,""))}
E34: {=IF($D34="","",xlookup($D34,PRODUCT!$B:$B,PRODUCT!$A:$A,""))} | F34: {=IF($D34="","",xlookup($D34,PRODUCT!$B:$B,PRODUCT!$C:$C,""))} | H34: {=IF($D34="","",xlookup($D34,PRODUCT!$B:$B,PRODUCT!$L:$L,""))} | I34: {=IF($D34="","",xlookup($D34,PRODUCT!$B:$B,PRODUCT!$M:$M,""))}
... E500: {=IF($D500="","",xlookup($D500,PRODUCT!$B:$B,PRODUCT!$A:$A,""))} | F500: {=IF($D500="","",xlookup($D500,PRODUCT!$B:$B,PRODUCT!$C:$C,""))} | H500: {=IF($D500="","",xlookup($D500,PRODUCT!$B:$B,PRODUCT!$L:$L,""))} | I500: {=IF($D500="","",xlookup($D500,PRODUCT!$B:$B,PRODUCT!$M:$M,""))}

Sheet INPUT_PRODUCT
A1: Cliente | B1: Francisco Flores
A2: Proyecto | B2: Palmira
A3: SRL | B3: xxxxxx
A4: Responsable | B4: Ana Mar Pérez
A5: Fecha | B5: 46120.802
A6: N_COTIZACION
A7: Incoterm | B7: =CONFIG!B7
A8: Condiciones_Pago
A9: Validez (días) | B9: =CONFIG!B6
A10: Plazo Entrega (semanas)
A11: Moneda | B11: =CONFIG!B8
A12: AREA_TOTAL_REFERENCIAL_M2 | B12: 100
A13: Observaciones_Generales
A14: ITEM | B14: INCLUIR | C14: SKU_FASSA | D14: FAMILIA | E14: NOMBRE_PRODUCTO | F14: CANTIDAD_BASE | G14: UNIDAD_INPUT | H14: FACTOR_AJUSTE | I14: CANTIDAD_MANUAL_OVERRIDE | J14: CANTIDAD_FINAL_INPUT | K14: MARGEN_%_APLICADO | L14: OBSERVACION_ITEM
A15: 1 | B15: SI | D15: =IF(C15="";"";INDEX(PRODUCT!A:A;MATCH(C15;PRODUCT!B:B;0))) | E15: =IF(C15="";"";VLOOKUP(C15;PRODUCT!B:C;2;FALSE)) | H15: 1 | J15: =IF(I15<>"";I15;F15*H15) | K15: =CONFIG!$B$6
A16: 2 | B16: SI | D16: =IF(C16="";"";INDEX(PRODUCT!A:A;MATCH(C16;PRODUCT!B:B;0))) | E16: =IF(C16="";"";VLOOKUP(C16;PRODUCT!B:C;2;FALSE)) | H16: 1 | J16: =IF(I16<>"";I16;F16*H16) | K16: =CONFIG!$B$6
A17: 3 | B17: SI | D17: =IF(C17="";"";INDEX(PRODUCT!A:A;MATCH(C17;PRODUCT!B:B;0))) | E17: =IF(C17="";"";VLOOKUP(C17;PRODUCT!B:C;2;FALSE)) | H17: 1 | J17: =IF(I17<>"";I17;F17*H17) | K17: =CONFIG!$B$6
A18: 4 | B18: SI | D18: =IF(C18="";"";INDEX(PRODUCT!A:A;MATCH(C18;PRODUCT!B:B;0))) | E18: =IF(C18="";"";VLOOKUP(C18;PRODUCT!B:C;2;FALSE)) | H18: 1 | J18: =IF(I18<>"";I18;F18*H18) | K18: =CONFIG!$B$6
A19: 5 | B19: SI | D19: =IF(C19="";"";INDEX(PRODUCT!A:A;MATCH(C19;PRODUCT!B:B;0))) | E19: =IF(C19="";"";VLOOKUP(C19;PRODUCT!B:C;2;FALSE)) | H19: 1 | J19: =IF(I19<>"";I19;F19*H19) | K19: =CONFIG!$B$6
A20: 6 | B20: SI | D20: =IF(C20="";"";INDEX(PRODUCT!A:A;MATCH(C20;PRODUCT!B:B;0))) | E20: =IF(C20="";"";VLOOKUP(C20;PRODUCT!B:C;2;FALSE)) | H20: 1 | J20: =IF(I20<>"";I20;F20*H20) | K20: =CONFIG!$B$6
A21: 7 | B21: SI | D21: =IF(C21="";"";INDEX(PRODUCT!A:A;MATCH(C21;PRODUCT!B:B;0))) | E21: =IF(C21="";"";VLOOKUP(C21;PRODUCT!B:C;2;FALSE)) | H21: 1 | J21: =IF(I21<>"";I21;F21*H21) | K21: =CONFIG!$B$6
A22: 8 | B22: SI | D22: =IF(C22="";"";INDEX(PRODUCT!A:A;MATCH(C22;PRODUCT!B:B;0))) | E22: =IF(C22="";"";VLOOKUP(C22;PRODUCT!B:C;2;FALSE)) | H22: 1 | J22: =IF(I22<>"";I22;F22*H22) | K22: =CONFIG!$B$6
A23: 9 | B23: SI | D23: =IF(C23="";"";INDEX(PRODUCT!A:A;MATCH(C23;PRODUCT!B:B;0))) | E23: =IF(C23="";"";VLOOKUP(C23;PRODUCT!B:C;2;FALSE)) | H23: 1 | J23: =IF(I23<>"";I23;F23*H23) | K23: =CONFIG!$B$6
A24: 10 | B24: SI | D24: =IF(C24="";"";INDEX(PRODUCT!A:A;MATCH(C24;PRODUCT!B:B;0))) | E24: =IF(C24="";"";VLOOKUP(C24;PRODUCT!B:C;2;FALSE)) | H24: 1 | J24: =IF(I24<>"";I24;F24*H24) | K24: =CONFIG!$B$6
A25: 11 | B25: SI | D25: =IF(C25="";"";INDEX(PRODUCT!A:A;MATCH(C25;PRODUCT!B:B;0))) | E25: =IF(C25="";"";VLOOKUP(C25;PRODUCT!B:C;2;FALSE)) | H25: 1 | J25: =IF(I25<>"";I25;F25*H25) | K25: =CONFIG!$B$6
A26: 12 | B26: SI | D26: =IF(C26="";"";INDEX(PRODUCT!A:A;MATCH(C26;PRODUCT!B:B;0))) | E26: =IF(C26="";"";VLOOKUP(C26;PRODUCT!B:C;2;FALSE)) | H26: 1 | J26: =IF(I26<>"";I26;F26*H26) | K26: =CONFIG!$B$6
... A200: 186 | B200: SI | D200: =IF(C200="";"";INDEX(PRODUCT!A:A;MATCH(C200;PRODUCT!B:B;0))) | E200: =IF(C200="";"";VLOOKUP(C200;PRODUCT!B:C;2;FALSE)) | H200: 1 | J200: =IF(I200<>"";I200;F200*H200) | K200: =CONFIG!$B$6

Sheet SYSTEM_CALCULATION
A1: ITEM | B1: GRUPO_COMPOSICION | C1: SKU_FASSA | D1: FAMILIA | E1: NOMBRE_PRODUCTO | F1: UNIDAD_PRECIO | G1: UDS_POR_PALE | H1: M2_POR_PALE_O_EQUIVALENTE | I1: AREA_APLICADA_M2 | J1: RENDIMIENTO_APLICADO | K1: MERMA_% | L1: FACTOR_AJUSTE | M1: CANTIDAD_MANUAL_OVERRIDE | N1: CANTIDAD_TECNICA | O1: UNIDADES_SUMINISTRO | P1: PRECIO_BASE_ARIAS_EUR | Q1: MARGEN_%_APLICADO | R1: PRECIO_UNITARIO_CLIENTE_EUR | S1: SUBTOTAL_INTERNO_EUR | T1: SUBTOTAL_CLIENTE_EUR | U1: INCLUIR | V1: OBSERVACION_ITEM
A2: =INPUT_SYSTEM!A2 | B2: =INPUT_SYSTEM!B2 | C2: =INPUT_SYSTEM!D2 | D2: {=IFERROR(XLOOKUP($C2,PRODUCT!B:B,PRODUCT!A:A),"")} | E2: =IF(C2="","",INPUT_SYSTEM!F16) | F2: {=IFERROR(INDEX(PRODUCT!$D:$D,MATCH(C2,PRODUCT!$B:$B,0)),"")} | G2: {=IFERROR(INDEX(PRODUCT!$E:$E,MATCH(C2,PRODUCT!$B:$B,0)),"")} | H2: {=IFERROR(INDEX(PRODUCT!$F:$F,MATCH(C2,PRODUCT!$B:$B,0)),"")} | I2: =IF(C2="","",INPUT_SYSTEM!G16) | J2: =IF(C2="","",INPUT_SYSTEM!H16) | K2: =IF(C2="","",INPUT_SYSTEM!J16) | L2: =IF(C2="","",INPUT_SYSTEM!K16) | M2: =IF(C2="","",INPUT_SYSTEM!L16) | N2: =IF(U2<>"SI","",IF(M2<>"",M2,IFERROR(I2*J2*(1+K2)*L2,""))) | O2: =IF(N2="","",IF(OR(H2="",H2=0),N2,ROUNDUP(N2/H2,0))) | P2: {=IFERROR(INDEX(PRODUCT!$I:$I,MATCH(C2,PRODUCT!$B:$B,0)),"")} | Q2: =IF(C2="","",INPUT_SYSTEM!M16) | R2: =IF(P2="","",P2*(1+Q2)) | S2: =IF(O2="","",IF(OR(H2="",H2=0),O2*P2,O2*H2*P2)) | T2: =IF(O2="","",IF(OR(H2="",H2=0),O2*R2,O2*H2*R2)) | U2: =IF(C2="","",INPUT_SYSTEM!C16) | V2: =IF(C2="","",INPUT_SYSTEM!N16)
A3: =IF(INPUT_SYSTEM!D17="","",INPUT_SYSTEM!A17) | B3: =IF(INPUT_SYSTEM!D17="","",INPUT_SYSTEM!B17) | C3: =IF(INPUT_SYSTEM!D17="","",INPUT_SYSTEM!D17) | D3: =IF(C3="","",INPUT_SYSTEM!E17) | E3: =IF(C3="","",INPUT_SYSTEM!F17) | F3: {=IFERROR(INDEX(PRODUCT!$D:$D,MATCH(C3,PRODUCT!$B:$B,0)),"")} | G3: {=IFERROR(INDEX(PRODUCT!$E:$E,MATCH(C3,PRODUCT!$B:$B,0)),"")} | H3: {=IFERROR(INDEX(PRODUCT!$F:$F,MATCH(C3,PRODUCT!$B:$B,0)),"")} | I3: =IF(C3="","",INPUT_SYSTEM!G17) | J3: =IF(C3="","",INPUT_SYSTEM!H17) | K3: =IF(C3="","",INPUT_SYSTEM!J17) | L3: =IF(C3="","",INPUT_SYSTEM!K17) | M3: =IF(C3="","",INPUT_SYSTEM!L17) | N3: =IF(U3<>"SI","",IF(M3<>"",M3,IFERROR(I3*J3*(1+K3)*L3,""))) | O3: =IF(N3="","",IF(OR(H3="",H3=0),N3,ROUNDUP(N3/H3,0))) | P3: {=IFERROR(INDEX(PRODUCT!$I:$I,MATCH(C3,PRODUCT!$B:$B,0)),"")} | Q3: =IF(C3="","",INPUT_SYSTEM!M17) | R3: =IF(P3="","",P3*(1+Q3)) | S3: =IF(O3="","",IF(OR(H3="",H3=0),O3*P3,O3*H3*P3)) | T3: =IF(O3="","",IF(OR(H3="",H3=0),O3*R3,O3*H3*R3)) | U3: =IF(C3="","",INPUT_SYSTEM!C17) | V3: =IF(C3="","",INPUT_SYSTEM!N17)
A4: =IF(INPUT_SYSTEM!D18="","",INPUT_SYSTEM!A18) | B4: =IF(INPUT_SYSTEM!D18="","",INPUT_SYSTEM!B18) | C4: =IF(INPUT_SYSTEM!D18="","",INPUT_SYSTEM!D18) | D4: =IF(C4="","",INPUT_SYSTEM!E18) | E4: =IF(C4="","",INPUT_SYSTEM!F18) | F4: {=IFERROR(INDEX(PRODUCT!$D:$D,MATCH(C4,PRODUCT!$B:$B,0)),"")} | G4: {=IFERROR(INDEX(PRODUCT!$E:$E,MATCH(C4,PRODUCT!$B:$B,0)),"")} | H4: {=IFERROR(INDEX(PRODUCT!$F:$F,MATCH(C4,PRODUCT!$B:$B,0)),"")} | I4: =IF(C4="","",INPUT_SYSTEM!G18) | J4: =IF(C4="","",INPUT_SYSTEM!H18) | K4: =IF(C4="","",INPUT_SYSTEM!J18) | L4: =IF(C4="","",INPUT_SYSTEM!K18) | M4: =IF(C4="","",INPUT_SYSTEM!L18) | N4: =IF(U4<>"SI","",IF(M4<>"",M4,IFERROR(I4*J4*(1+K4)*L4,""))) | O4: =IF(N4="","",IF(OR(H4="",H4=0),N4,ROUNDUP(N4/H4,0))) | P4: {=IFERROR(INDEX(PRODUCT!$I:$I,MATCH(C4,PRODUCT!$B:$B,0)),"")} | Q4: =IF(C4="","",INPUT_SYSTEM!M18) | R4: =IF(P4="","",P4*(1+Q4)) | S4: =IF(O4="","",IF(OR(H4="",H4=0),O4*P4,O4*H4*P4)) | T4: =IF(O4="","",IF(OR(H4="",H4=0),O4*R4,O4*H4*R4)) | U4: =IF(C4="","",INPUT_SYSTEM!C18) | V4: =IF(C4="","",INPUT_SYSTEM!N18)
A5: =IF(INPUT_SYSTEM!D19="","",INPUT_SYSTEM!A19) | B5: =IF(INPUT_SYSTEM!D19="","",INPUT_SYSTEM!B19) | C5: =IF(INPUT_SYSTEM!D19="","",INPUT_SYSTEM!D19) | D5: =IF(C5="","",INPUT_SYSTEM!E19) | E5: =IF(C5="","",INPUT_SYSTEM!F19) | F5: {=IFERROR(INDEX(PRODUCT!$D:$D,MATCH(C5,PRODUCT!$B:$B,0)),"")} | G5: {=IFERROR(INDEX(PRODUCT!$E:$E,MATCH(C5,PRODUCT!$B:$B,0)),"")} | H5: {=IFERROR(INDEX(PRODUCT!$F:$F,MATCH(C5,PRODUCT!$B:$B,0)),"")} | I5: =IF(C5="","",INPUT_SYSTEM!G19) | J5: =IF(C5="","",INPUT_SYSTEM!H19) | K5: =IF(C5="","",INPUT_SYSTEM!J19) | L5: =IF(C5="","",INPUT_SYSTEM!K19) | M5: =IF(C5="","",INPUT_SYSTEM!L19) | N5: =IF(U5<>"SI","",IF(M5<>"",M5,IFERROR(I5*J5*(1+K5)*L5,""))) | O5: =IF(N5="","",IF(OR(H5="",H5=0),N5,ROUNDUP(N5/H5,0))) | P5: {=IFERROR(INDEX(PRODUCT!$I:$I,MATCH(C5,PRODUCT!$B:$B,0)),"")} | Q5: =IF(C5="","",INPUT_SYSTEM!M19) | R5: =IF(P5="","",P5*(1+Q5)) | S5: =IF(O5="","",IF(OR(H5="",H5=0),O5*P5,O5*H5*P5)) | T5: =IF(O5="","",IF(OR(H5="",H5=0),O5*R5,O5*H5*R5)) | U5: =IF(C5="","",INPUT_SYSTEM!C19) | V5: =IF(C5="","",INPUT_SYSTEM!N19)
A6: =IF(INPUT_SYSTEM!D20="","",INPUT_SYSTEM!A20) | B6: =IF(INPUT_SYSTEM!D20="","",INPUT_SYSTEM!B20) | C6: =IF(INPUT_SYSTEM!D20="","",INPUT_SYSTEM!D20) | D6: =IF(C6="","",INPUT_SYSTEM!E20) | E6: =IF(C6="","",INPUT_SYSTEM!F20) | F6: {=IFERROR(INDEX(PRODUCT!$D:$D,MATCH(C6,PRODUCT!$B:$B,0)),"")} | G6: {=IFERROR(INDEX(PRODUCT!$E:$E,MATCH(C6,PRODUCT!$B:$B,0)),"")} | H6: {=IFERROR(INDEX(PRODUCT!$F:$F,MATCH(C6,PRODUCT!$B:$B,0)),"")} | I6: =IF(C6="","",INPUT_SYSTEM!G20) | J6: =IF(C6="","",INPUT_SYSTEM!H20) | K6: =IF(C6="","",INPUT_SYSTEM!J20) | L6: =IF(C6="","",INPUT_SYSTEM!K20) | M6: =IF(C6="","",INPUT_SYSTEM!L20) | N6: =IF(U6<>"SI","",IF(M6<>"",M6,IFERROR(I6*J6*(1+K6)*L6,""))) | O6: =IF(N6="","",IF(OR(H6="",H6=0),N6,ROUNDUP(N6/H6,0))) | P6: {=IFERROR(INDEX(PRODUCT!$I:$I,MATCH(C6,PRODUCT!$B:$B,0)),"")} | Q6: =IF(C6="","",INPUT_SYSTEM!M20) | R6: =IF(P6="","",P6*(1+Q6)) | S6: =IF(O6="","",IF(OR(H6="",H6=0),O6*P6,O6*H6*P6)) | T6: =IF(O6="","",IF(OR(H6="",H6=0),O6*R6,O6*H6*R6)) | U6: =IF(C6="","",INPUT_SYSTEM!C20) | V6: =IF(C6="","",INPUT_SYSTEM!N20)
A7: =IF(INPUT_SYSTEM!D21="","",INPUT_SYSTEM!A21) | B7: =IF(INPUT_SYSTEM!D21="","",INPUT_SYSTEM!B21) | C7: =IF(INPUT_SYSTEM!D21="","",INPUT_SYSTEM!D21) | D7: =IF(C7="","",INPUT_SYSTEM!E21) | E7: =IF(C7="","",INPUT_SYSTEM!F21) | F7: {=IFERROR(INDEX(PRODUCT!$D:$D,MATCH(C7,PRODUCT!$B:$B,0)),"")} | G7: {=IFERROR(INDEX(PRODUCT!$E:$E,MATCH(C7,PRODUCT!$B:$B,0)),"")} | H7: {=IFERROR(INDEX(PRODUCT!$F:$F,MATCH(C7,PRODUCT!$B:$B,0)),"")} | I7: =IF(C7="","",INPUT_SYSTEM!G21) | J7: =IF(C7="","",INPUT_SYSTEM!H21) | K7: =IF(C7="","",INPUT_SYSTEM!J21) | L7: =IF(C7="","",INPUT_SYSTEM!K21) | M7: =IF(C7="","",INPUT_SYSTEM!L21) | N7: =IF(U7<>"SI","",IF(M7<>"",M7,IFERROR(I7*J7*(1+K7)*L7,""))) | O7: =IF(N7="","",IF(OR(H7="",H7=0),N7,ROUNDUP(N7/H7,0))) | P7: {=IFERROR(INDEX(PRODUCT!$I:$I,MATCH(C7,PRODUCT!$B:$B,0)),"")} | Q7: =IF(C7="","",INPUT_SYSTEM!M21) | R7: =IF(P7="","",P7*(1+Q7)) | S7: =IF(O7="","",IF(OR(H7="",H7=0),O7*P7,O7*H7*P7)) | T7: =IF(O7="","",IF(OR(H7="",H7=0),O7*R7,O7*H7*R7)) | U7: =IF(C7="","",INPUT_SYSTEM!C21) | V7: =IF(C7="","",INPUT_SYSTEM!N21)
A8: =IF(INPUT_SYSTEM!D22="","",INPUT_SYSTEM!A22) | B8: =IF(INPUT_SYSTEM!D22="","",INPUT_SYSTEM!B22) | C8: =IF(INPUT_SYSTEM!D22="","",INPUT_SYSTEM!D22) | D8: =IF(C8="","",INPUT_SYSTEM!E22) | E8: =IF(C8="","",INPUT_SYSTEM!F22) | F8: {=IFERROR(INDEX(PRODUCT!$D:$D,MATCH(C8,PRODUCT!$B:$B,0)),"")} | G8: {=IFERROR(INDEX(PRODUCT!$E:$E,MATCH(C8,PRODUCT!$B:$B,0)),"")} | H8: {=IFERROR(INDEX(PRODUCT!$F:$F,MATCH(C8,PRODUCT!$B:$B,0)),"")} | I8: =IF(C8="","",INPUT_SYSTEM!G22) | J8: =IF(C8="","",INPUT_SYSTEM!H22) | K8: =IF(C8="","",INPUT_SYSTEM!J22) | L8: =IF(C8="","",INPUT_SYSTEM!K22) | M8: =IF(C8="","",INPUT_SYSTEM!L22) | N8: =IF(U8<>"SI","",IF(M8<>"",M8,IFERROR(I8*J8*(1+K8)*L8,""))) | O8: =IF(N8="","",IF(OR(H8="",H8=0),N8,ROUNDUP(N8/H8,0))) | P8: {=IFERROR(INDEX(PRODUCT!$I:$I,MATCH(C8,PRODUCT!$B:$B,0)),"")} | Q8: =IF(C8="","",INPUT_SYSTEM!M22) | R8: =IF(P8="","",P8*(1+Q8)) | S8: =IF(O8="","",IF(OR(H8="",H8=0),O8*P8,O8*H8*P8)) | T8: =IF(O8="","",IF(OR(H8="",H8=0),O8*R8,O8*H8*R8)) | U8: =IF(C8="","",INPUT_SYSTEM!C22) | V8: =IF(C8="","",INPUT_SYSTEM!N22)
A9: =IF(INPUT_SYSTEM!D23="","",INPUT_SYSTEM!A23) | B9: =IF(INPUT_SYSTEM!D23="","",INPUT_SYSTEM!B23) | C9: =IF(INPUT_SYSTEM!D23="","",INPUT_SYSTEM!D23) | D9: =IF(C9="","",INPUT_SYSTEM!E23) | E9: =IF(C9="","",INPUT_SYSTEM!F23) | F9: {=IFERROR(INDEX(PRODUCT!$D:$D,MATCH(C9,PRODUCT!$B:$B,0)),"")} | G9: {=IFERROR(INDEX(PRODUCT!$E:$E,MATCH(C9,PRODUCT!$B:$B,0)),"")} | H9: {=IFERROR(INDEX(PRODUCT!$F:$F,MATCH(C9,PRODUCT!$B:$B,0)),"")} | I9: =IF(C9="","",INPUT_SYSTEM!G23) | J9: =IF(C9="","",INPUT_SYSTEM!H23) | K9: =IF(C9="","",INPUT_SYSTEM!J23) | L9: =IF(C9="","",INPUT_SYSTEM!K23) | M9: =IF(C9="","",INPUT_SYSTEM!L23) | N9: =IF(U9<>"SI","",IF(M9<>"",M9,IFERROR(I9*J9*(1+K9)*L9,""))) | O9: =IF(N9="","",IF(OR(H9="",H9=0),N9,ROUNDUP(N9/H9,0))) | P9: {=IFERROR(INDEX(PRODUCT!$I:$I,MATCH(C9,PRODUCT!$B:$B,0)),"")} | Q9: =IF(C9="","",INPUT_SYSTEM!M23) | R9: =IF(P9="","",P9*(1+Q9)) | S9: =IF(O9="","",IF(OR(H9="",H9=0),O9*P9,O9*H9*P9)) | T9: =IF(O9="","",IF(OR(H9="",H9=0),O9*R9,O9*H9*R9)) | U9: =IF(C9="","",INPUT_SYSTEM!C23) | V9: =IF(C9="","",INPUT_SYSTEM!N23)
A10: =IF(INPUT_SYSTEM!D24="","",INPUT_SYSTEM!A24) | B10: =IF(INPUT_SYSTEM!D24="","",INPUT_SYSTEM!B24) | C10: =IF(INPUT_SYSTEM!D24="","",INPUT_SYSTEM!D24) | D10: =IF(C10="","",INPUT_SYSTEM!E24) | E10: =IF(C10="","",INPUT_SYSTEM!F24) | F10: {=IFERROR(INDEX(PRODUCT!$D:$D,MATCH(C10,PRODUCT!$B:$B,0)),"")} | G10: {=IFERROR(INDEX(PRODUCT!$E:$E,MATCH(C10,PRODUCT!$B:$B,0)),"")} | H10: {=IFERROR(INDEX(PRODUCT!$F:$F,MATCH(C10,PRODUCT!$B:$B,0)),"")} | I10: =IF(C10="","",INPUT_SYSTEM!G24) | J10: =IF(C10="","",INPUT_SYSTEM!H24) | K10: =IF(C10="","",INPUT_SYSTEM!J24) | L10: =IF(C10="","",INPUT_SYSTEM!K24) | M10: =IF(C10="","",INPUT_SYSTEM!L24) | N10: =IF(U10<>"SI","",IF(M10<>"",M10,IFERROR(I10*J10*(1+K10)*L10,""))) | O10: =IF(N10="","",IF(OR(H10="",H10=0),N10,ROUNDUP(N10/H10,0))) | P10: {=IFERROR(INDEX(PRODUCT!$I:$I,MATCH(C10,PRODUCT!$B:$B,0)),"")} | Q10: =IF(C10="","",INPUT_SYSTEM!M24) | R10: =IF(P10="","",P10*(1+Q10)) | S10: =IF(O10="","",IF(OR(H10="",H10=0),O10*P10,O10*H10*P10)) | T10: =IF(O10="","",IF(OR(H10="",H10=0),O10*R10,O10*H10*R10)) | U10: =IF(C10="","",INPUT_SYSTEM!C24) | V10: =IF(C10="","",INPUT_SYSTEM!N24)
A11: =IF(INPUT_SYSTEM!D25="","",INPUT_SYSTEM!A25) | B11: =IF(INPUT_SYSTEM!D25="","",INPUT_SYSTEM!B25) | C11: =IF(INPUT_SYSTEM!D25="","",INPUT_SYSTEM!D25) | D11: =IF(C11="","",INPUT_SYSTEM!E25) | E11: =IF(C11="","",INPUT_SYSTEM!F25) | F11: {=IFERROR(INDEX(PRODUCT!$D:$D,MATCH(C11,PRODUCT!$B:$B,0)),"")} | G11: {=IFERROR(INDEX(PRODUCT!$E:$E,MATCH(C11,PRODUCT!$B:$B,0)),"")} | H11: {=IFERROR(INDEX(PRODUCT!$F:$F,MATCH(C11,PRODUCT!$B:$B,0)),"")} | I11: =IF(C11="","",INPUT_SYSTEM!G25) | J11: =IF(C11="","",INPUT_SYSTEM!H25) | K11: =IF(C11="","",INPUT_SYSTEM!J25) | L11: =IF(C11="","",INPUT_SYSTEM!K25) | M11: =IF(C11="","",INPUT_SYSTEM!L25) | N11: =IF(U11<>"SI","",IF(M11<>"",M11,IFERROR(I11*J11*(1+K11)*L11,""))) | O11: =IF(N11="","",IF(OR(H11="",H11=0),N11,ROUNDUP(N11/H11,0))) | P11: {=IFERROR(INDEX(PRODUCT!$I:$I,MATCH(C11,PRODUCT!$B:$B,0)),"")} | Q11: =IF(C11="","",INPUT_SYSTEM!M25) | R11: =IF(P11="","",P11*(1+Q11)) | S11: =IF(O11="","",IF(OR(H11="",H11=0),O11*P11,O11*H11*P11)) | T11: =IF(O11="","",IF(OR(H11="",H11=0),O11*R11,O11*H11*R11)) | U11: =IF(C11="","",INPUT_SYSTEM!C25) | V11: =IF(C11="","",INPUT_SYSTEM!N25)
A12: =IF(INPUT_SYSTEM!D26="","",INPUT_SYSTEM!A26) | B12: =IF(INPUT_SYSTEM!D26="","",INPUT_SYSTEM!B26) | C12: =IF(INPUT_SYSTEM!D26="","",INPUT_SYSTEM!D26) | D12: =IF(C12="","",INPUT_SYSTEM!E26) | E12: =IF(C12="","",INPUT_SYSTEM!F26) | F12: {=IFERROR(INDEX(PRODUCT!$D:$D,MATCH(C12,PRODUCT!$B:$B,0)),"")} | G12: {=IFERROR(INDEX(PRODUCT!$E:$E,MATCH(C12,PRODUCT!$B:$B,0)),"")} | H12: {=IFERROR(INDEX(PRODUCT!$F:$F,MATCH(C12,PRODUCT!$B:$B,0)),"")} | I12: =IF(C12="","",INPUT_SYSTEM!G26) | J12: =IF(C12="","",INPUT_SYSTEM!H26) | K12: =IF(C12="","",INPUT_SYSTEM!J26) | L12: =IF(C12="","",INPUT_SYSTEM!K26) | M12: =IF(C12="","",INPUT_SYSTEM!L26) | N12: =IF(U12<>"SI","",IF(M12<>"",M12,IFERROR(I12*J12*(1+K12)*L12,""))) | O12: =IF(N12="","",IF(OR(H12="",H12=0),N12,ROUNDUP(N12/H12,0))) | P12: {=IFERROR(INDEX(PRODUCT!$I:$I,MATCH(C12,PRODUCT!$B:$B,0)),"")} | Q12: =IF(C12="","",INPUT_SYSTEM!M26) | R12: =IF(P12="","",P12*(1+Q12)) | S12: =IF(O12="","",IF(OR(H12="",H12=0),O12*P12,O12*H12*P12)) | T12: =IF(O12="","",IF(OR(H12="",H12=0),O12*R12,O12*H12*R12)) | U12: =IF(C12="","",INPUT_SYSTEM!C26) | V12: =IF(C12="","",INPUT_SYSTEM!N26)
A13: =IF(INPUT_SYSTEM!D27="","",INPUT_SYSTEM!A27) | B13: =IF(INPUT_SYSTEM!D27="","",INPUT_SYSTEM!B27) | C13: =IF(INPUT_SYSTEM!D27="","",INPUT_SYSTEM!D27) | D13: =IF(C13="","",INPUT_SYSTEM!E27) | E13: =IF(C13="","",INPUT_SYSTEM!F27) | F13: {=IFERROR(INDEX(PRODUCT!$D:$D,MATCH(C13,PRODUCT!$B:$B,0)),"")} | G13: {=IFERROR(INDEX(PRODUCT!$E:$E,MATCH(C13,PRODUCT!$B:$B,0)),"")} | H13: {=IFERROR(INDEX(PRODUCT!$F:$F,MATCH(C13,PRODUCT!$B:$B,0)),"")} | I13: =IF(C13="","",INPUT_SYSTEM!G27) | J13: =IF(C13="","",INPUT_SYSTEM!H27) | K13: =IF(C13="","",INPUT_SYSTEM!J27) | L13: =IF(C13="","",INPUT_SYSTEM!K27) | M13: =IF(C13="","",INPUT_SYSTEM!L27) | N13: =IF(U13<>"SI","",IF(M13<>"",M13,IFERROR(I13*J13*(1+K13)*L13,""))) | O13: =IF(N13="","",IF(OR(H13="",H13=0),N13,ROUNDUP(N13/H13,0))) | P13: {=IFERROR(INDEX(PRODUCT!$I:$I,MATCH(C13,PRODUCT!$B:$B,0)),"")} | Q13: =IF(C13="","",INPUT_SYSTEM!M27) | R13: =IF(P13="","",P13*(1+Q13)) | S13: =IF(O13="","",IF(OR(H13="",H13=0),O13*P13,O13*H13*P13)) | T13: =IF(O13="","",IF(OR(H13="",H13=0),O13*R13,O13*H13*R13)) | U13: =IF(C13="","",INPUT_SYSTEM!C27) | V13: =IF(C13="","",INPUT_SYSTEM!N27)
A14: =IF(INPUT_SYSTEM!D28="","",INPUT_SYSTEM!A28) | B14: =IF(INPUT_SYSTEM!D28="","",INPUT_SYSTEM!B28) | C14: =IF(INPUT_SYSTEM!D28="","",INPUT_SYSTEM!D28) | D14: =IF(C14="","",INPUT_SYSTEM!E28) | E14: =IF(C14="","",INPUT_SYSTEM!F28) | F14: {=IFERROR(INDEX(PRODUCT!$D:$D,MATCH(C14,PRODUCT!$B:$B,0)),"")} | G14: {=IFERROR(INDEX(PRODUCT!$E:$E,MATCH(C14,PRODUCT!$B:$B,0)),"")} | H14: {=IFERROR(INDEX(PRODUCT!$F:$F,MATCH(C14,PRODUCT!$B:$B,0)),"")} | I14: =IF(C14="","",INPUT_SYSTEM!G28) | J14: =IF(C14="","",INPUT_SYSTEM!H28) | K14: =IF(C14="","",INPUT_SYSTEM!J28) | L14: =IF(C14="","",INPUT_SYSTEM!K28) | M14: =IF(C14="","",INPUT_SYSTEM!L28) | N14: =IF(U14<>"SI","",IF(M14<>"",M14,IFERROR(I14*J14*(1+K14)*L14,""))) | O14: =IF(N14="","",IF(OR(H14="",H14=0),N14,ROUNDUP(N14/H14,0))) | P14: {=IFERROR(INDEX(PRODUCT!$I:$I,MATCH(C14,PRODUCT!$B:$B,0)),"")} | Q14: =IF(C14="","",INPUT_SYSTEM!M28) | R14: =IF(P14="","",P14*(1+Q14)) | S14: =IF(O14="","",IF(OR(H14="",H14=0),O14*P14,O14*H14*P14)) | T14: =IF(O14="","",IF(OR(H14="",H14=0),O14*R14,O14*H14*R14)) | U14: =IF(C14="","",INPUT_SYSTEM!C28) | V14: =IF(C14="","",INPUT_SYSTEM!N28)
... A250: =IF(INPUT_SYSTEM!D264="","",INPUT_SYSTEM!A264) | B250: =IF(INPUT_SYSTEM!D264="","",INPUT_SYSTEM!B264) | C250: =IF(INPUT_SYSTEM!D264="","",INPUT_SYSTEM!D264) | D250: =IF(C250="","",INPUT_SYSTEM!E264) | E250: =IF(C250="","",INPUT_SYSTEM!F264) | F250: {=IFERROR(INDEX(PRODUCT!$D:$D,MATCH(C250,PRODUCT!$B:$B,0)),"")} | G250: {=IFERROR(INDEX(PRODUCT!$E:$E,MATCH(C250,PRODUCT!$B:$B,0)),"")} | H250: {=IFERROR(INDEX(PRODUCT!$F:$F,MATCH(C250,PRODUCT!$B:$B,0)),"")} | I250: =IF(C250="","",INPUT_SYSTEM!G264) | J250: =IF(C250="","",INPUT_SYSTEM!H264) | K250: =IF(C250="","",INPUT_SYSTEM!J264) | L250: =IF(C250="","",INPUT_SYSTEM!K264) | M250: =IF(C250="","",INPUT_SYSTEM!L264) | N250: =IF(U250<>"SI","",IF(M250<>"",M250,IFERROR(I250*J250*(1+K250)*L250,""))) | O250: =IF(N250="","",IF(OR(H250="",H250=0),N250,ROUNDUP(N250/H250,0))) | P250: {=IFERROR(INDEX(PRODUCT!$I:$I,MATCH(C250,PRODUCT!$B:$B,0)),"")} | Q250: =IF(C250="","",INPUT_SYSTEM!M264) | R250: =IF(P250="","",P250*(1+Q250)) | S250: =IF(O250="","",IF(OR(H250="",H250=0),O250*P250,O250*H250*P250)) | T250: =IF(O250="","",IF(OR(H250="",H250=0),O250*R250,O250*H250*R250)) | U250: =IF(C250="","",INPUT_SYSTEM!C264) | V250: =IF(C250="","",INPUT_SYSTEM!N264)
A251: =IF(INPUT_SYSTEM!D265="","",INPUT_SYSTEM!A265) | B251: =IF(INPUT_SYSTEM!D265="","",INPUT_SYSTEM!B265) | C251: =IF(INPUT_SYSTEM!D265="","",INPUT_SYSTEM!D265) | D251: =IF(C251="","",INPUT_SYSTEM!E265) | E251: =IF(C251="","",INPUT_SYSTEM!F265) | F251: {=IFERROR(INDEX(PRODUCT!$D:$D,MATCH(C251,PRODUCT!$B:$B,0)),"")} | G251: {=IFERROR(INDEX(PRODUCT!$E:$E,MATCH(C251,PRODUCT!$B:$B,0)),"")} | H251: {=IFERROR(INDEX(PRODUCT!$F:$F,MATCH(C251,PRODUCT!$B:$B,0)),"")} | I251: =IF(C251="","",INPUT_SYSTEM!G265) | J251: =IF(C251="","",INPUT_SYSTEM!H265) | K251: =IF(C251="","",INPUT_SYSTEM!J265) | L251: =IF(C251="","",INPUT_SYSTEM!K265) | M251: =IF(C251="","",INPUT_SYSTEM!L265) | N251: =IF(U251<>"SI","",IF(M251<>"",M251,IFERROR(I251*J251*(1+K251)*L251,""))) | O251: =IF(N251="","",IF(OR(H251="",H251=0),N251,ROUNDUP(N251/H251,0))) | P251: {=IFERROR(INDEX(PRODUCT!$I:$I,MATCH(C251,PRODUCT!$B:$B,0)),"")} | Q251: =IF(C251="","",INPUT_SYSTEM!M265) | R251: =IF(P251="","",P251*(1+Q251)) | S251: =IF(O251="","",IF(OR(H251="",H251=0),O251*P251,O251*H251*P251)) | T251: =IF(O251="","",IF(OR(H251="",H251=0),O251*R251,O251*H251*R251)) | U251: =IF(C251="","",INPUT_SYSTEM!C265)
A252: =IF(INPUT_SYSTEM!D266="","",INPUT_SYSTEM!A266) | B252: =IF(INPUT_SYSTEM!D266="","",INPUT_SYSTEM!B266) | C252: =IF(INPUT_SYSTEM!D266="","",INPUT_SYSTEM!D266) | D252: =IF(C252="","",INPUT_SYSTEM!E266) | E252: =IF(C252="","",INPUT_SYSTEM!F266) | F252: {=IFERROR(INDEX(PRODUCT!$D:$D,MATCH(C252,PRODUCT!$B:$B,0)),"")} | G252: {=IFERROR(INDEX(PRODUCT!$E:$E,MATCH(C252,PRODUCT!$B:$B,0)),"")} | H252: {=IFERROR(INDEX(PRODUCT!$F:$F,MATCH(C252,PRODUCT!$B:$B,0)),"")} | I252: =IF(C252="","",INPUT_SYSTEM!G266) | J252: =IF(C252="","",INPUT_SYSTEM!H266) | K252: =IF(C252="","",INPUT_SYSTEM!J266) | L252: =IF(C252="","",INPUT_SYSTEM!K266) | M252: =IF(C252="","",INPUT_SYSTEM!L266) | N252: =IF(U252<>"SI","",IF(M252<>"",M252,IFERROR(I252*J252*(1+K252)*L252,""))) | O252: =IF(N252="","",IF(OR(H252="",H252=0),N252,ROUNDUP(N252/H252,0))) | P252: {=IFERROR(INDEX(PRODUCT!$I:$I,MATCH(C252,PRODUCT!$B:$B,0)),"")} | Q252: =IF(C252="","",INPUT_SYSTEM!M266) | R252: =IF(P252="","",P252*(1+Q252)) | S252: =IF(O252="","",IF(OR(H252="",H252=0),O252*P252,O252*H252*P252)) | T252: =IF(O252="","",IF(OR(H252="",H252=0),O252*R252,O252*H252*R252)) | U252: =IF(C252="","",INPUT_SYSTEM!C266)
A253: =IF(INPUT_SYSTEM!D267="","",INPUT_SYSTEM!A267) | B253: =IF(INPUT_SYSTEM!D267="","",INPUT_SYSTEM!B267) | C253: =IF(INPUT_SYSTEM!D267="","",INPUT_SYSTEM!D267) | D253: =IF(C253="","",INPUT_SYSTEM!E267) | E253: =IF(C253="","",INPUT_SYSTEM!F267) | F253: {=IFERROR(INDEX(PRODUCT!$D:$D,MATCH(C253,PRODUCT!$B:$B,0)),"")} | G253: {=IFERROR(INDEX(PRODUCT!$E:$E,MATCH(C253,PRODUCT!$B:$B,0)),"")} | H253: {=IFERROR(INDEX(PRODUCT!$F:$F,MATCH(C253,PRODUCT!$B:$B,0)),"")} | I253: =IF(C253="","",INPUT_SYSTEM!G267) | J253: =IF(C253="","",INPUT_SYSTEM!H267) | K253: =IF(C253="","",INPUT_SYSTEM!J267) | L253: =IF(C253="","",INPUT_SYSTEM!K267) | M253: =IF(C253="","",INPUT_SYSTEM!L267) | N253: =IF(U253<>"SI","",IF(M253<>"",M253,IFERROR(I253*J253*(1+K253)*L253,""))) | O253: =IF(N253="","",IF(OR(H253="",H253=0),N253,ROUNDUP(N253/H253,0))) | P253: {=IFERROR(INDEX(PRODUCT!$I:$I,MATCH(C253,PRODUCT!$B:$B,0)),"")} | Q253: =IF(C253="","",INPUT_SYSTEM!M267) | R253: =IF(P253="","",P253*(1+Q253)) | S253: =IF(O253="","",IF(OR(H253="",H253=0),O253*P253,O253*H253*P253)) | T253: =IF(O253="","",IF(OR(H253="",H253=0),O253*R253,O253*H253*R253)) | U253: =IF(C253="","",INPUT_SYSTEM!C267)
A254: =IF(INPUT_SYSTEM!D268="","",INPUT_SYSTEM!A268) | B254: =IF(INPUT_SYSTEM!D268="","",INPUT_SYSTEM!B268) | C254: =IF(INPUT_SYSTEM!D268="","",INPUT_SYSTEM!D268) | D254: =IF(C254="","",INPUT_SYSTEM!E268) | E254: =IF(C254="","",INPUT_SYSTEM!F268) | F254: {=IFERROR(INDEX(PRODUCT!$D:$D,MATCH(C254,PRODUCT!$B:$B,0)),"")} | G254: {=IFERROR(INDEX(PRODUCT!$E:$E,MATCH(C254,PRODUCT!$B:$B,0)),"")} | H254: {=IFERROR(INDEX(PRODUCT!$F:$F,MATCH(C254,PRODUCT!$B:$B,0)),"")} | I254: =IF(C254="","",INPUT_SYSTEM!G268) | J254: =IF(C254="","",INPUT_SYSTEM!H268) | K254: =IF(C254="","",INPUT_SYSTEM!J268) | L254: =IF(C254="","",INPUT_SYSTEM!K268) | M254: =IF(C254="","",INPUT_SYSTEM!L268) | N254: =IF(U254<>"SI","",IF(M254<>"",M254,IFERROR(I254*J254*(1+K254)*L254,""))) | O254: =IF(N254="","",IF(OR(H254="",H254=0),N254,ROUNDUP(N254/H254,0))) | P254: {=IFERROR(INDEX(PRODUCT!$I:$I,MATCH(C254,PRODUCT!$B:$B,0)),"")} | Q254: =IF(C254="","",INPUT_SYSTEM!M268) | R254: =IF(P254="","",P254*(1+Q254)) | S254: =IF(O254="","",IF(OR(H254="",H254=0),O254*P254,O254*H254*P254)) | T254: =IF(O254="","",IF(OR(H254="",H254=0),O254*R254,O254*H254*R254)) | U254: =IF(C254="","",INPUT_SYSTEM!C268)
A255: =IF(INPUT_SYSTEM!D269="","",INPUT_SYSTEM!A269) | B255: =IF(INPUT_SYSTEM!D269="","",INPUT_SYSTEM!B269) | C255: =IF(INPUT_SYSTEM!D269="","",INPUT_SYSTEM!D269) | D255: =IF(C255="","",INPUT_SYSTEM!E269) | E255: =IF(C255="","",INPUT_SYSTEM!F269) | F255: {=IFERROR(INDEX(PRODUCT!$D:$D,MATCH(C255,PRODUCT!$B:$B,0)),"")} | G255: {=IFERROR(INDEX(PRODUCT!$E:$E,MATCH(C255,PRODUCT!$B:$B,0)),"")} | H255: {=IFERROR(INDEX(PRODUCT!$F:$F,MATCH(C255,PRODUCT!$B:$B,0)),"")} | I255: =IF(C255="","",INPUT_SYSTEM!G269) | J255: =IF(C255="","",INPUT_SYSTEM!H269) | K255: =IF(C255="","",INPUT_SYSTEM!J269) | L255: =IF(C255="","",INPUT_SYSTEM!K269) | M255: =IF(C255="","",INPUT_SYSTEM!L269) | N255: =IF(U255<>"SI","",IF(M255<>"",M255,IFERROR(I255*J255*(1+K255)*L255,""))) | O255: =IF(N255="","",IF(OR(H255="",H255=0),N255,ROUNDUP(N255/H255,0))) | P255: {=IFERROR(INDEX(PRODUCT!$I:$I,MATCH(C255,PRODUCT!$B:$B,0)),"")} | Q255: =IF(C255="","",INPUT_SYSTEM!M269) | R255: =IF(P255="","",P255*(1+Q255)) | S255: =IF(O255="","",IF(OR(H255="",H255=0),O255*P255,O255*H255*P255)) | T255: =IF(O255="","",IF(OR(H255="",H255=0),O255*R255,O255*H255*R255)) | U255: =IF(C255="","",INPUT_SYSTEM!C269)
A256: =IF(INPUT_SYSTEM!D270="","",INPUT_SYSTEM!A270) | B256: =IF(INPUT_SYSTEM!D270="","",INPUT_SYSTEM!B270) | C256: =IF(INPUT_SYSTEM!D270="","",INPUT_SYSTEM!D270) | D256: =IF(C256="","",INPUT_SYSTEM!E270) | E256: =IF(C256="","",INPUT_SYSTEM!F270) | F256: {=IFERROR(INDEX(PRODUCT!$D:$D,MATCH(C256,PRODUCT!$B:$B,0)),"")} | G256: {=IFERROR(INDEX(PRODUCT!$E:$E,MATCH(C256,PRODUCT!$B:$B,0)),"")} | H256: {=IFERROR(INDEX(PRODUCT!$F:$F,MATCH(C256,PRODUCT!$B:$B,0)),"")} | I256: =IF(C256="","",INPUT_SYSTEM!G270) | J256: =IF(C256="","",INPUT_SYSTEM!H270) | K256: =IF(C256="","",INPUT_SYSTEM!J270) | L256: =IF(C256="","",INPUT_SYSTEM!K270) | M256: =IF(C256="","",INPUT_SYSTEM!L270) | N256: =IF(U256<>"SI","",IF(M256<>"",M256,IFERROR(I256*J256*(1+K256)*L256,""))) | O256: =IF(N256="","",IF(OR(H256="",H256=0),N256,ROUNDUP(N256/H256,0))) | P256: {=IFERROR(INDEX(PRODUCT!$I:$I,MATCH(C256,PRODUCT!$B:$B,0)),"")} | Q256: =IF(C256="","",INPUT_SYSTEM!M270) | R256: =IF(P256="","",P256*(1+Q256)) | S256: =IF(O256="","",IF(OR(H256="",H256=0),O256*P256,O256*H256*P256)) | T256: =IF(O256="","",IF(OR(H256="",H256=0),O256*R256,O256*H256*R256)) | U256: =IF(C256="","",INPUT_SYSTEM!C270)
A257: =IF(INPUT_SYSTEM!D271="","",INPUT_SYSTEM!A271) | B257: =IF(INPUT_SYSTEM!D271="","",INPUT_SYSTEM!B271) | C257: =IF(INPUT_SYSTEM!D271="","",INPUT_SYSTEM!D271) | D257: =IF(C257="","",INPUT_SYSTEM!E271) | E257: =IF(C257="","",INPUT_SYSTEM!F271) | F257: {=IFERROR(INDEX(PRODUCT!$D:$D,MATCH(C257,PRODUCT!$B:$B,0)),"")} | G257: {=IFERROR(INDEX(PRODUCT!$E:$E,MATCH(C257,PRODUCT!$B:$B,0)),"")} | H257: {=IFERROR(INDEX(PRODUCT!$F:$F,MATCH(C257,PRODUCT!$B:$B,0)),"")} | I257: =IF(C257="","",INPUT_SYSTEM!G271) | J257: =IF(C257="","",INPUT_SYSTEM!H271) | K257: =IF(C257="","",INPUT_SYSTEM!J271) | L257: =IF(C257="","",INPUT_SYSTEM!K271) | M257: =IF(C257="","",INPUT_SYSTEM!L271) | N257: =IF(U257<>"SI","",IF(M257<>"",M257,IFERROR(I257*J257*(1+K257)*L257,""))) | O257: =IF(N257="","",IF(OR(H257="",H257=0),N257,ROUNDUP(N257/H257,0))) | P257: {=IFERROR(INDEX(PRODUCT!$I:$I,MATCH(C257,PRODUCT!$B:$B,0)),"")} | Q257: =IF(C257="","",INPUT_SYSTEM!M271) | R257: =IF(P257="","",P257*(1+Q257)) | S257: =IF(O257="","",IF(OR(H257="",H257=0),O257*P257,O257*H257*P257)) | T257: =IF(O257="","",IF(OR(H257="",H257=0),O257*R257,O257*H257*R257)) | U257: =IF(C257="","",INPUT_SYSTEM!C271)
A258: =IF(INPUT_SYSTEM!D272="","",INPUT_SYSTEM!A272) | B258: =IF(INPUT_SYSTEM!D272="","",INPUT_SYSTEM!B272) | C258: =IF(INPUT_SYSTEM!D272="","",INPUT_SYSTEM!D272) | D258: =IF(C258="","",INPUT_SYSTEM!E272) | E258: =IF(C258="","",INPUT_SYSTEM!F272) | F258: {=IFERROR(INDEX(PRODUCT!$D:$D,MATCH(C258,PRODUCT!$B:$B,0)),"")} | G258: {=IFERROR(INDEX(PRODUCT!$E:$E,MATCH(C258,PRODUCT!$B:$B,0)),"")} | H258: {=IFERROR(INDEX(PRODUCT!$F:$F,MATCH(C258,PRODUCT!$B:$B,0)),"")} | I258: =IF(C258="","",INPUT_SYSTEM!G272) | J258: =IF(C258="","",INPUT_SYSTEM!H272) | K258: =IF(C258="","",INPUT_SYSTEM!J272) | L258: =IF(C258="","",INPUT_SYSTEM!K272) | M258: =IF(C258="","",INPUT_SYSTEM!L272) | N258: =IF(U258<>"SI","",IF(M258<>"",M258,IFERROR(I258*J258*(1+K258)*L258,""))) | O258: =IF(N258="","",IF(OR(H258="",H258=0),N258,ROUNDUP(N258/H258,0))) | P258: {=IFERROR(INDEX(PRODUCT!$I:$I,MATCH(C258,PRODUCT!$B:$B,0)),"")} | Q258: =IF(C258="","",INPUT_SYSTEM!M272) | R258: =IF(P258="","",P258*(1+Q258)) | S258: =IF(O258="","",IF(OR(H258="",H258=0),O258*P258,O258*H258*P258)) | T258: =IF(O258="","",IF(OR(H258="",H258=0),O258*R258,O258*H258*R258)) | U258: =IF(C258="","",INPUT_SYSTEM!C272)
A259: =IF(INPUT_SYSTEM!D273="","",INPUT_SYSTEM!A273) | B259: =IF(INPUT_SYSTEM!D273="","",INPUT_SYSTEM!B273) | C259: =IF(INPUT_SYSTEM!D273="","",INPUT_SYSTEM!D273) | D259: =IF(C259="","",INPUT_SYSTEM!E273) | E259: =IF(C259="","",INPUT_SYSTEM!F273) | F259: {=IFERROR(INDEX(PRODUCT!$D:$D,MATCH(C259,PRODUCT!$B:$B,0)),"")} | G259: {=IFERROR(INDEX(PRODUCT!$E:$E,MATCH(C259,PRODUCT!$B:$B,0)),"")} | H259: {=IFERROR(INDEX(PRODUCT!$F:$F,MATCH(C259,PRODUCT!$B:$B,0)),"")} | I259: =IF(C259="","",INPUT_SYSTEM!G273) | J259: =IF(C259="","",INPUT_SYSTEM!H273) | K259: =IF(C259="","",INPUT_SYSTEM!J273) | L259: =IF(C259="","",INPUT_SYSTEM!K273) | M259: =IF(C259="","",INPUT_SYSTEM!L273) | N259: =IF(U259<>"SI","",IF(M259<>"",M259,IFERROR(I259*J259*(1+K259)*L259,""))) | O259: =IF(N259="","",IF(OR(H259="",H259=0),N259,ROUNDUP(N259/H259,0))) | P259: {=IFERROR(INDEX(PRODUCT!$I:$I,MATCH(C259,PRODUCT!$B:$B,0)),"")} | Q259: =IF(C259="","",INPUT_SYSTEM!M273) | R259: =IF(P259="","",P259*(1+Q259)) | S259: =IF(O259="","",IF(OR(H259="",H259=0),O259*P259,O259*H259*P259)) | T259: =IF(O259="","",IF(OR(H259="",H259=0),O259*R259,O259*H259*R259)) | U259: =IF(C259="","",INPUT_SYSTEM!C273)
A260: =IF(INPUT_SYSTEM!D274="","",INPUT_SYSTEM!A274) | B260: =IF(INPUT_SYSTEM!D274="","",INPUT_SYSTEM!B274) | C260: =IF(INPUT_SYSTEM!D274="","",INPUT_SYSTEM!D274) | D260: =IF(C260="","",INPUT_SYSTEM!E274) | E260: =IF(C260="","",INPUT_SYSTEM!F274) | F260: {=IFERROR(INDEX(PRODUCT!$D:$D,MATCH(C260,PRODUCT!$B:$B,0)),"")} | G260: {=IFERROR(INDEX(PRODUCT!$E:$E,MATCH(C260,PRODUCT!$B:$B,0)),"")} | H260: {=IFERROR(INDEX(PRODUCT!$F:$F,MATCH(C260,PRODUCT!$B:$B,0)),"")} | I260: =IF(C260="","",INPUT_SYSTEM!G274) | J260: =IF(C260="","",INPUT_SYSTEM!H274) | K260: =IF(C260="","",INPUT_SYSTEM!J274) | L260: =IF(C260="","",INPUT_SYSTEM!K274) | M260: =IF(C260="","",INPUT_SYSTEM!L274) | N260: =IF(U260<>"SI","",IF(M260<>"",M260,IFERROR(I260*J260*(1+K260)*L260,""))) | O260: =IF(N260="","",IF(OR(H260="",H260=0),N260,ROUNDUP(N260/H260,0))) | P260: {=IFERROR(INDEX(PRODUCT!$I:$I,MATCH(C260,PRODUCT!$B:$B,0)),"")} | Q260: =IF(C260="","",INPUT_SYSTEM!M274) | R260: =IF(P260="","",P260*(1+Q260)) | S260: =IF(O260="","",IF(OR(H260="",H260=0),O260*P260,O260*H260*P260)) | T260: =IF(O260="","",IF(OR(H260="",H260=0),O260*R260,O260*H260*R260)) | U260: =IF(C260="","",INPUT_SYSTEM!C274)
